--------------------
Failed to process https://github.com/mechio/takana.git repo
Traceback (most recent call last):
  File "/style-analyzer/lookout/style/format/benchmarks/quality_report.py", line 312, in generate_quality_report
    vnodes_expected_number=vnodes_expected_number)
  File "/style-analyzer/lookout/style/format/benchmarks/quality_report.py", line 137, in measure_quality
    bblfsh=bblfsh, config_json=config)
  File "/lookout-sdk-ml/lookout/core/helpers/analyzer_context_manager.py", line 87, in review
    log_level=log_level, config_json=config_json)
  File "/lookout-sdk-ml/lookout/core/helpers/server.py", line 101, in review
    return self._run("review", fr, to, port, git_dir, bblfsh, log_level, config_json)
  File "/lookout-sdk-ml/lookout/core/helpers/server.py", line 131, in _run
    return subprocess.run(command, stdout=subprocess.PIPE, stderr=subprocess.PIPE, check=True)
  File "/usr/lib/python3.6/subprocess.py", line 418, in run
    output=stdout, stderr=stderr)
subprocess.CalledProcessError: Command '['/tmp/lookout-sdk-ml/lookout-sdk-v0.7.0', 'review', 'ipv4://localhost:19508', '--from', 'a0cce72b5702842229358f6af7934e31875a659c', '--to', '3e274d5990392590ce44b00f1c0acd680f98cf7b', '--git-dir', '/tmp/top-repos-quality-repos-0k69ofza/takana.git', '--log-format', 'json', '--log-level', 'warning', '--config-json', '{"style.format.analyzer.FormatAnalyzer": {"aggregate": true}}']' returned non-zero exit status 1.
--------------------
Failed to process https://github.com/kickscondor/fraidycat.git repo
Traceback (most recent call last):
  File "/style-analyzer/lookout/style/format/benchmarks/quality_report.py", line 312, in generate_quality_report
    vnodes_expected_number=vnodes_expected_number)
  File "/style-analyzer/lookout/style/format/benchmarks/quality_report.py", line 137, in measure_quality
    bblfsh=bblfsh, config_json=config)
  File "/lookout-sdk-ml/lookout/core/helpers/analyzer_context_manager.py", line 87, in review
    log_level=log_level, config_json=config_json)
  File "/lookout-sdk-ml/lookout/core/helpers/server.py", line 101, in review
    return self._run("review", fr, to, port, git_dir, bblfsh, log_level, config_json)
  File "/lookout-sdk-ml/lookout/core/helpers/server.py", line 131, in _run
    return subprocess.run(command, stdout=subprocess.PIPE, stderr=subprocess.PIPE, check=True)
  File "/usr/lib/python3.6/subprocess.py", line 418, in run
    output=stdout, stderr=stderr)
subprocess.CalledProcessError: Command '['/tmp/lookout-sdk-ml/lookout-sdk-v0.7.0', 'review', 'ipv4://localhost:19508', '--from', '664ab8cee487b03d9915f3308715958703d40bcd', '--to', 'a5480cfaf37953463598892f977ce53069a40a69', '--git-dir', '/tmp/top-repos-quality-repos-0c7js089/fraidycat.git', '--log-format', 'json', '--log-level', 'warning', '--config-json', '{"style.format.analyzer.FormatAnalyzer": {"aggregate": true}}']' returned non-zero exit status 1.
--------------------
Failed to process https://github.com/apachecn/apachecn-algo-zh.git repo
Traceback (most recent call last):
  File "/style-analyzer/lookout/style/format/benchmarks/quality_report.py", line 312, in generate_quality_report
    vnodes_expected_number=vnodes_expected_number)
  File "/style-analyzer/lookout/style/format/benchmarks/quality_report.py", line 137, in measure_quality
    bblfsh=bblfsh, config_json=config)
  File "/lookout-sdk-ml/lookout/core/helpers/analyzer_context_manager.py", line 87, in review
    log_level=log_level, config_json=config_json)
  File "/lookout-sdk-ml/lookout/core/helpers/server.py", line 101, in review
    return self._run("review", fr, to, port, git_dir, bblfsh, log_level, config_json)
  File "/lookout-sdk-ml/lookout/core/helpers/server.py", line 131, in _run
    return subprocess.run(command, stdout=subprocess.PIPE, stderr=subprocess.PIPE, check=True)
  File "/usr/lib/python3.6/subprocess.py", line 418, in run
    output=stdout, stderr=stderr)
subprocess.CalledProcessError: Command '['/tmp/lookout-sdk-ml/lookout-sdk-v0.7.0', 'review', 'ipv4://localhost:19508', '--from', '8c0bee04fc7ca4e22e50023b76620c1458e6b8ae', '--to', '71862d95dd7e1e34c8e193b3ebf1063172a2cbf0', '--git-dir', '/tmp/top-repos-quality-repos-0zep0p4t/apachecn-algo-zh.git', '--log-format', 'json', '--log-level', 'warning', '--config-json', '{"style.format.analyzer.FormatAnalyzer": {"aggregate": true}}']' returned non-zero exit status 1.
--------------------
Failed to process https://github.com/shaunlebron/parinfer.git repo
Traceback (most recent call last):
  File "/style-analyzer/lookout/style/format/benchmarks/quality_report.py", line 312, in generate_quality_report
    vnodes_expected_number=vnodes_expected_number)
  File "/style-analyzer/lookout/style/format/benchmarks/quality_report.py", line 137, in measure_quality
    bblfsh=bblfsh, config_json=config)
  File "/lookout-sdk-ml/lookout/core/helpers/analyzer_context_manager.py", line 87, in review
    log_level=log_level, config_json=config_json)
  File "/lookout-sdk-ml/lookout/core/helpers/server.py", line 101, in review
    return self._run("review", fr, to, port, git_dir, bblfsh, log_level, config_json)
  File "/lookout-sdk-ml/lookout/core/helpers/server.py", line 131, in _run
    return subprocess.run(command, stdout=subprocess.PIPE, stderr=subprocess.PIPE, check=True)
  File "/usr/lib/python3.6/subprocess.py", line 418, in run
    output=stdout, stderr=stderr)
subprocess.CalledProcessError: Command '['/tmp/lookout-sdk-ml/lookout-sdk-v0.7.0', 'review', 'ipv4://localhost:19508', '--from', 'f2e3320bcde6a95f4fb653386ef9c9c22ed3420f', '--to', '41c74d03534a5adbdcb7430fb666899e8dbf746d', '--git-dir', '/tmp/top-repos-quality-repos-95srqcz1/parinfer.git', '--log-format', 'json', '--log-level', 'warning', '--config-json', '{"style.format.analyzer.FormatAnalyzer": {"aggregate": true}}']' returned non-zero exit status 1.
--------------------
Failed to process https://github.com/lukeed/uvu.git repo
Traceback (most recent call last):
  File "/style-analyzer/lookout/style/format/benchmarks/quality_report.py", line 312, in generate_quality_report
    vnodes_expected_number=vnodes_expected_number)
  File "/style-analyzer/lookout/style/format/benchmarks/quality_report.py", line 137, in measure_quality
    bblfsh=bblfsh, config_json=config)
  File "/lookout-sdk-ml/lookout/core/helpers/analyzer_context_manager.py", line 87, in review
    log_level=log_level, config_json=config_json)
  File "/lookout-sdk-ml/lookout/core/helpers/server.py", line 101, in review
    return self._run("review", fr, to, port, git_dir, bblfsh, log_level, config_json)
  File "/lookout-sdk-ml/lookout/core/helpers/server.py", line 131, in _run
    return subprocess.run(command, stdout=subprocess.PIPE, stderr=subprocess.PIPE, check=True)
  File "/usr/lib/python3.6/subprocess.py", line 418, in run
    output=stdout, stderr=stderr)
subprocess.CalledProcessError: Command '['/tmp/lookout-sdk-ml/lookout-sdk-v0.7.0', 'review', 'ipv4://localhost:19508', '--from', '988d9290adef593aaf3ee169868b9fcef0d9d0f3', '--to', 'd56753ec20928da1c22ff093cb07ce3c67613706', '--git-dir', '/tmp/top-repos-quality-repos-jopsxinh/uvu.git', '--log-format', 'json', '--log-level', 'warning', '--config-json', '{"style.format.analyzer.FormatAnalyzer": {"aggregate": true}}']' returned non-zero exit status 1.
--------------------
Failed to process https://github.com/affinelayer/pix2pix-tensorflow.git repo
Traceback (most recent call last):
  File "/style-analyzer/lookout/style/format/benchmarks/quality_report.py", line 312, in generate_quality_report
    vnodes_expected_number=vnodes_expected_number)
  File "/style-analyzer/lookout/style/format/benchmarks/quality_report.py", line 137, in measure_quality
    bblfsh=bblfsh, config_json=config)
  File "/lookout-sdk-ml/lookout/core/helpers/analyzer_context_manager.py", line 87, in review
    log_level=log_level, config_json=config_json)
  File "/lookout-sdk-ml/lookout/core/helpers/server.py", line 101, in review
    return self._run("review", fr, to, port, git_dir, bblfsh, log_level, config_json)
  File "/lookout-sdk-ml/lookout/core/helpers/server.py", line 131, in _run
    return subprocess.run(command, stdout=subprocess.PIPE, stderr=subprocess.PIPE, check=True)
  File "/usr/lib/python3.6/subprocess.py", line 418, in run
    output=stdout, stderr=stderr)
subprocess.CalledProcessError: Command '['/tmp/lookout-sdk-ml/lookout-sdk-v0.7.0', 'review', 'ipv4://localhost:19508', '--from', '5c761a294e0ddd5a43fa2bb3de110f46e7a8f30a', '--to', '0f2174424356162920fc25067e63db2bcf19f4e7', '--git-dir', '/tmp/top-repos-quality-repos-gfwyrrh4/pix2pix-tensorflow.git', '--log-format', 'json', '--log-level', 'warning', '--config-json', '{"style.format.analyzer.FormatAnalyzer": {"aggregate": true}}']' returned non-zero exit status 1.
--------------------
Failed to process https://github.com/prettier/prettier-eslint.git repo
Traceback (most recent call last):
  File "/style-analyzer/lookout/style/format/benchmarks/quality_report.py", line 312, in generate_quality_report
    vnodes_expected_number=vnodes_expected_number)
  File "/style-analyzer/lookout/style/format/benchmarks/quality_report.py", line 137, in measure_quality
    bblfsh=bblfsh, config_json=config)
  File "/lookout-sdk-ml/lookout/core/helpers/analyzer_context_manager.py", line 87, in review
    log_level=log_level, config_json=config_json)
  File "/lookout-sdk-ml/lookout/core/helpers/server.py", line 101, in review
    return self._run("review", fr, to, port, git_dir, bblfsh, log_level, config_json)
  File "/lookout-sdk-ml/lookout/core/helpers/server.py", line 131, in _run
    return subprocess.run(command, stdout=subprocess.PIPE, stderr=subprocess.PIPE, check=True)
  File "/usr/lib/python3.6/subprocess.py", line 418, in run
    output=stdout, stderr=stderr)
subprocess.CalledProcessError: Command '['/tmp/lookout-sdk-ml/lookout-sdk-v0.7.0', 'review', 'ipv4://localhost:19508', '--from', 'db6f7cb0abadf1bef27ab4bdd058bfa37b7af361', '--to', 'c62769ef430749fb9650c7e1d05f5cf7442a48a2', '--git-dir', '/tmp/top-repos-quality-repos-bzxj59gz/prettier-eslint.git', '--log-format', 'json', '--log-level', 'warning', '--config-json', '{"style.format.analyzer.FormatAnalyzer": {"aggregate": true}}']' returned non-zero exit status 1.
--------------------
Failed to process https://github.com/mandatoryprogrammer/cursedchrome.git repo
Traceback (most recent call last):
  File "/style-analyzer/lookout/style/format/benchmarks/quality_report.py", line 312, in generate_quality_report
    vnodes_expected_number=vnodes_expected_number)
  File "/style-analyzer/lookout/style/format/benchmarks/quality_report.py", line 137, in measure_quality
    bblfsh=bblfsh, config_json=config)
  File "/lookout-sdk-ml/lookout/core/helpers/analyzer_context_manager.py", line 87, in review
    log_level=log_level, config_json=config_json)
  File "/lookout-sdk-ml/lookout/core/helpers/server.py", line 101, in review
    return self._run("review", fr, to, port, git_dir, bblfsh, log_level, config_json)
  File "/lookout-sdk-ml/lookout/core/helpers/server.py", line 131, in _run
    return subprocess.run(command, stdout=subprocess.PIPE, stderr=subprocess.PIPE, check=True)
  File "/usr/lib/python3.6/subprocess.py", line 418, in run
    output=stdout, stderr=stderr)
subprocess.CalledProcessError: Command '['/tmp/lookout-sdk-ml/lookout-sdk-v0.7.0', 'review', 'ipv4://localhost:19508', '--from', 'f7c0dd87d73238f2ef3d631d6db90e5f490cebe0', '--to', 'f18eaee6e3aee866b801235e836d9576aff008de', '--git-dir', '/tmp/top-repos-quality-repos-7yp9tpqm/cursedchrome.git', '--log-format', 'json', '--log-level', 'warning', '--config-json', '{"style.format.analyzer.FormatAnalyzer": {"aggregate": true}}']' returned non-zero exit status 1.
--------------------
Failed to process https://github.com/disease-sh/api.git repo
Traceback (most recent call last):
  File "/style-analyzer/lookout/style/format/benchmarks/quality_report.py", line 312, in generate_quality_report
    vnodes_expected_number=vnodes_expected_number)
  File "/style-analyzer/lookout/style/format/benchmarks/quality_report.py", line 137, in measure_quality
    bblfsh=bblfsh, config_json=config)
  File "/lookout-sdk-ml/lookout/core/helpers/analyzer_context_manager.py", line 87, in review
    log_level=log_level, config_json=config_json)
  File "/lookout-sdk-ml/lookout/core/helpers/server.py", line 101, in review
    return self._run("review", fr, to, port, git_dir, bblfsh, log_level, config_json)
  File "/lookout-sdk-ml/lookout/core/helpers/server.py", line 131, in _run
    return subprocess.run(command, stdout=subprocess.PIPE, stderr=subprocess.PIPE, check=True)
  File "/usr/lib/python3.6/subprocess.py", line 418, in run
    output=stdout, stderr=stderr)
subprocess.CalledProcessError: Command '['/tmp/lookout-sdk-ml/lookout-sdk-v0.7.0', 'review', 'ipv4://localhost:19508', '--from', 'da39023402eaea84409f7a495eca9fd21935b8c3', '--to', '3ba2eac0e7c9093852bdd3400c7f2581cd74ac9e', '--git-dir', '/tmp/top-repos-quality-repos-qnjlurhz/api.git', '--log-format', 'json', '--log-level', 'warning', '--config-json', '{"style.format.analyzer.FormatAnalyzer": {"aggregate": true}}']' returned non-zero exit status 1.
--------------------
Failed to process https://github.com/coffe1891/frontend-hard-mode-interview.git repo
Traceback (most recent call last):
  File "/style-analyzer/lookout/style/format/benchmarks/quality_report.py", line 312, in generate_quality_report
    vnodes_expected_number=vnodes_expected_number)
  File "/style-analyzer/lookout/style/format/benchmarks/quality_report.py", line 137, in measure_quality
    bblfsh=bblfsh, config_json=config)
  File "/lookout-sdk-ml/lookout/core/helpers/analyzer_context_manager.py", line 87, in review
    log_level=log_level, config_json=config_json)
  File "/lookout-sdk-ml/lookout/core/helpers/server.py", line 101, in review
    return self._run("review", fr, to, port, git_dir, bblfsh, log_level, config_json)
  File "/lookout-sdk-ml/lookout/core/helpers/server.py", line 131, in _run
    return subprocess.run(command, stdout=subprocess.PIPE, stderr=subprocess.PIPE, check=True)
  File "/usr/lib/python3.6/subprocess.py", line 418, in run
    output=stdout, stderr=stderr)
subprocess.CalledProcessError: Command '['/tmp/lookout-sdk-ml/lookout-sdk-v0.7.0', 'review', 'ipv4://localhost:19508', '--from', '6d11051ec005ed2fc897b8028e1ddb5473618c81', '--to', 'ffb7ff24d792522f8294fc81abe3ac6381053c1e', '--git-dir', '/tmp/top-repos-quality-repos-0opmycgw/frontend-hard-mode-interview.git', '--log-format', 'json', '--log-level', 'warning', '--config-json', '{"style.format.analyzer.FormatAnalyzer": {"aggregate": true}}']' returned non-zero exit status 1.
--------------------
Failed to process https://github.com/electerious/ackee.git repo
Traceback (most recent call last):
  File "/style-analyzer/lookout/style/format/benchmarks/quality_report.py", line 312, in generate_quality_report
    vnodes_expected_number=vnodes_expected_number)
  File "/style-analyzer/lookout/style/format/benchmarks/quality_report.py", line 137, in measure_quality
    bblfsh=bblfsh, config_json=config)
  File "/lookout-sdk-ml/lookout/core/helpers/analyzer_context_manager.py", line 87, in review
    log_level=log_level, config_json=config_json)
  File "/lookout-sdk-ml/lookout/core/helpers/server.py", line 101, in review
    return self._run("review", fr, to, port, git_dir, bblfsh, log_level, config_json)
  File "/lookout-sdk-ml/lookout/core/helpers/server.py", line 131, in _run
    return subprocess.run(command, stdout=subprocess.PIPE, stderr=subprocess.PIPE, check=True)
  File "/usr/lib/python3.6/subprocess.py", line 418, in run
    output=stdout, stderr=stderr)
subprocess.CalledProcessError: Command '['/tmp/lookout-sdk-ml/lookout-sdk-v0.7.0', 'review', 'ipv4://localhost:19508', '--from', '1710fcd013482a13faeb449fabd2728edf50adfb', '--to', '9a6e51d337ab7c9affdc6752e1acbe9405d0f633', '--git-dir', '/tmp/top-repos-quality-repos-rnwt388b/ackee.git', '--log-format', 'json', '--log-level', 'warning', '--config-json', '{"style.format.analyzer.FormatAnalyzer": {"aggregate": true}}']' returned non-zero exit status 1.
--------------------
Failed to process https://github.com/ines/termynal.git repo
Traceback (most recent call last):
  File "/style-analyzer/lookout/style/format/benchmarks/quality_report.py", line 312, in generate_quality_report
    vnodes_expected_number=vnodes_expected_number)
  File "/style-analyzer/lookout/style/format/benchmarks/quality_report.py", line 137, in measure_quality
    bblfsh=bblfsh, config_json=config)
  File "/lookout-sdk-ml/lookout/core/helpers/analyzer_context_manager.py", line 87, in review
    log_level=log_level, config_json=config_json)
  File "/lookout-sdk-ml/lookout/core/helpers/server.py", line 101, in review
    return self._run("review", fr, to, port, git_dir, bblfsh, log_level, config_json)
  File "/lookout-sdk-ml/lookout/core/helpers/server.py", line 131, in _run
    return subprocess.run(command, stdout=subprocess.PIPE, stderr=subprocess.PIPE, check=True)
  File "/usr/lib/python3.6/subprocess.py", line 418, in run
    output=stdout, stderr=stderr)
subprocess.CalledProcessError: Command '['/tmp/lookout-sdk-ml/lookout-sdk-v0.7.0', 'review', 'ipv4://localhost:19508', '--from', '39389bf5a3cf7ad5cceda733ea6a1c7ed6e9d532', '--to', '9b301892db6f8d403abfce7adf65888dffed72ea', '--git-dir', '/tmp/top-repos-quality-repos-mu_u1u2c/termynal.git', '--log-format', 'json', '--log-level', 'warning', '--config-json', '{"style.format.analyzer.FormatAnalyzer": {"aggregate": true}}']' returned non-zero exit status 1.
--------------------
Failed to process https://github.com/wordpress-mobile/wordpress-editor-ios.git repo
Traceback (most recent call last):
  File "/style-analyzer/lookout/style/format/benchmarks/quality_report.py", line 312, in generate_quality_report
    vnodes_expected_number=vnodes_expected_number)
  File "/style-analyzer/lookout/style/format/benchmarks/quality_report.py", line 137, in measure_quality
    bblfsh=bblfsh, config_json=config)
  File "/lookout-sdk-ml/lookout/core/helpers/analyzer_context_manager.py", line 87, in review
    log_level=log_level, config_json=config_json)
  File "/lookout-sdk-ml/lookout/core/helpers/server.py", line 101, in review
    return self._run("review", fr, to, port, git_dir, bblfsh, log_level, config_json)
  File "/lookout-sdk-ml/lookout/core/helpers/server.py", line 131, in _run
    return subprocess.run(command, stdout=subprocess.PIPE, stderr=subprocess.PIPE, check=True)
  File "/usr/lib/python3.6/subprocess.py", line 418, in run
    output=stdout, stderr=stderr)
subprocess.CalledProcessError: Command '['/tmp/lookout-sdk-ml/lookout-sdk-v0.7.0', 'review', 'ipv4://localhost:19508', '--from', '18115b109e90e91fb41fc7c062c84dee23f42ef7', '--to', 'b56b59e8f76b6eaf0bb378b487d7ec38db5a407e', '--git-dir', '/tmp/top-repos-quality-repos-caeu6s05/wordpress-editor-ios.git', '--log-format', 'json', '--log-level', 'warning', '--config-json', '{"style.format.analyzer.FormatAnalyzer": {"aggregate": true}}']' returned non-zero exit status 1.
--------------------
Failed to process https://github.com/alexmojaki/birdseye.git repo
Traceback (most recent call last):
  File "/style-analyzer/lookout/style/format/benchmarks/quality_report.py", line 312, in generate_quality_report
    vnodes_expected_number=vnodes_expected_number)
  File "/style-analyzer/lookout/style/format/benchmarks/quality_report.py", line 137, in measure_quality
    bblfsh=bblfsh, config_json=config)
  File "/lookout-sdk-ml/lookout/core/helpers/analyzer_context_manager.py", line 87, in review
    log_level=log_level, config_json=config_json)
  File "/lookout-sdk-ml/lookout/core/helpers/server.py", line 101, in review
    return self._run("review", fr, to, port, git_dir, bblfsh, log_level, config_json)
  File "/lookout-sdk-ml/lookout/core/helpers/server.py", line 131, in _run
    return subprocess.run(command, stdout=subprocess.PIPE, stderr=subprocess.PIPE, check=True)
  File "/usr/lib/python3.6/subprocess.py", line 418, in run
    output=stdout, stderr=stderr)
subprocess.CalledProcessError: Command '['/tmp/lookout-sdk-ml/lookout-sdk-v0.7.0', 'review', 'ipv4://localhost:19508', '--from', '7038bfe7dcd51cc8a079a9be33688d2b450e1c83', '--to', '0f0e0b40e16584d232587e0cffec41660a158aa0', '--git-dir', '/tmp/top-repos-quality-repos-x460rupi/birdseye.git', '--log-format', 'json', '--log-level', 'warning', '--config-json', '{"style.format.analyzer.FormatAnalyzer": {"aggregate": true}}']' returned non-zero exit status 1.
--------------------
Failed to process https://github.com/yangshun/tech-interview-handbook.git repo
Traceback (most recent call last):
  File "/style-analyzer/lookout/style/format/benchmarks/quality_report.py", line 312, in generate_quality_report
    vnodes_expected_number=vnodes_expected_number)
  File "/style-analyzer/lookout/style/format/benchmarks/quality_report.py", line 137, in measure_quality
    bblfsh=bblfsh, config_json=config)
  File "/lookout-sdk-ml/lookout/core/helpers/analyzer_context_manager.py", line 87, in review
    log_level=log_level, config_json=config_json)
  File "/lookout-sdk-ml/lookout/core/helpers/server.py", line 101, in review
    return self._run("review", fr, to, port, git_dir, bblfsh, log_level, config_json)
  File "/lookout-sdk-ml/lookout/core/helpers/server.py", line 131, in _run
    return subprocess.run(command, stdout=subprocess.PIPE, stderr=subprocess.PIPE, check=True)
  File "/usr/lib/python3.6/subprocess.py", line 418, in run
    output=stdout, stderr=stderr)
subprocess.CalledProcessError: Command '['/tmp/lookout-sdk-ml/lookout-sdk-v0.7.0', 'review', 'ipv4://localhost:19508', '--from', 'd0458155cf537b6db04da73d0556a0339b3ad26f', '--to', '89318237ccb161a786cc0b5b50a2d9a85b09a9d6', '--git-dir', '/tmp/top-repos-quality-repos-w2abz2lf/tech-interview-handbook.git', '--log-format', 'json', '--log-level', 'warning', '--config-json', '{"style.format.analyzer.FormatAnalyzer": {"aggregate": true}}']' returned non-zero exit status 1.
--------------------
Failed to process https://github.com/tengbao/vanta.git repo
Traceback (most recent call last):
  File "/style-analyzer/lookout/style/format/benchmarks/quality_report.py", line 312, in generate_quality_report
    vnodes_expected_number=vnodes_expected_number)
  File "/style-analyzer/lookout/style/format/benchmarks/quality_report.py", line 137, in measure_quality
    bblfsh=bblfsh, config_json=config)
  File "/lookout-sdk-ml/lookout/core/helpers/analyzer_context_manager.py", line 87, in review
    log_level=log_level, config_json=config_json)
  File "/lookout-sdk-ml/lookout/core/helpers/server.py", line 101, in review
    return self._run("review", fr, to, port, git_dir, bblfsh, log_level, config_json)
  File "/lookout-sdk-ml/lookout/core/helpers/server.py", line 131, in _run
    return subprocess.run(command, stdout=subprocess.PIPE, stderr=subprocess.PIPE, check=True)
  File "/usr/lib/python3.6/subprocess.py", line 418, in run
    output=stdout, stderr=stderr)
subprocess.CalledProcessError: Command '['/tmp/lookout-sdk-ml/lookout-sdk-v0.7.0', 'review', 'ipv4://localhost:19508', '--from', '9a6e92a53cb5531b72a976c126b78e0ead2991f9', '--to', '2f5cfabfd4388a362b337a9b74783cb96de92b4f', '--git-dir', '/tmp/top-repos-quality-repos-kuoa52m6/vanta.git', '--log-format', 'json', '--log-level', 'warning', '--config-json', '{"style.format.analyzer.FormatAnalyzer": {"aggregate": true}}']' returned non-zero exit status 1.
--------------------
Failed to process https://github.com/enzymejs/enzyme.git repo
Traceback (most recent call last):
  File "/style-analyzer/lookout/style/format/benchmarks/quality_report.py", line 312, in generate_quality_report
    vnodes_expected_number=vnodes_expected_number)
  File "/style-analyzer/lookout/style/format/benchmarks/quality_report.py", line 137, in measure_quality
    bblfsh=bblfsh, config_json=config)
  File "/lookout-sdk-ml/lookout/core/helpers/analyzer_context_manager.py", line 87, in review
    log_level=log_level, config_json=config_json)
  File "/lookout-sdk-ml/lookout/core/helpers/server.py", line 101, in review
    return self._run("review", fr, to, port, git_dir, bblfsh, log_level, config_json)
  File "/lookout-sdk-ml/lookout/core/helpers/server.py", line 131, in _run
    return subprocess.run(command, stdout=subprocess.PIPE, stderr=subprocess.PIPE, check=True)
  File "/usr/lib/python3.6/subprocess.py", line 418, in run
    output=stdout, stderr=stderr)
subprocess.CalledProcessError: Command '['/tmp/lookout-sdk-ml/lookout-sdk-v0.7.0', 'review', 'ipv4://localhost:19508', '--from', '081554e6295164ac88023823e352d06be9fa4e23', '--to', '8c55734eb19a2f7555eb3d695ae11401fa1f9847', '--git-dir', '/tmp/top-repos-quality-repos-dqb34jv9/enzyme.git', '--log-format', 'json', '--log-level', 'warning', '--config-json', '{"style.format.analyzer.FormatAnalyzer": {"aggregate": true}}']' returned non-zero exit status 1.
--------------------
Failed to process https://github.com/mathiasbynens/esrever.git repo
Traceback (most recent call last):
  File "/style-analyzer/lookout/style/format/benchmarks/quality_report.py", line 312, in generate_quality_report
    vnodes_expected_number=vnodes_expected_number)
  File "/style-analyzer/lookout/style/format/benchmarks/quality_report.py", line 137, in measure_quality
    bblfsh=bblfsh, config_json=config)
  File "/lookout-sdk-ml/lookout/core/helpers/analyzer_context_manager.py", line 87, in review
    log_level=log_level, config_json=config_json)
  File "/lookout-sdk-ml/lookout/core/helpers/server.py", line 101, in review
    return self._run("review", fr, to, port, git_dir, bblfsh, log_level, config_json)
  File "/lookout-sdk-ml/lookout/core/helpers/server.py", line 131, in _run
    return subprocess.run(command, stdout=subprocess.PIPE, stderr=subprocess.PIPE, check=True)
  File "/usr/lib/python3.6/subprocess.py", line 418, in run
    output=stdout, stderr=stderr)
subprocess.CalledProcessError: Command '['/tmp/lookout-sdk-ml/lookout-sdk-v0.7.0', 'review', 'ipv4://localhost:19508', '--from', '5d0299c38b66d2be536e4fd0999e5532ac5066c3', '--to', '14b34013dad49106ca08c0e65919f1fc8fea5331', '--git-dir', '/tmp/top-repos-quality-repos-vjw4rxeb/esrever.git', '--log-format', 'json', '--log-level', 'warning', '--config-json', '{"style.format.analyzer.FormatAnalyzer": {"aggregate": true}}']' returned non-zero exit status 1.
--------------------
Failed to process https://github.com/handlebars-lang/handlebars.js.git repo
Traceback (most recent call last):
  File "/style-analyzer/lookout/style/format/benchmarks/quality_report.py", line 312, in generate_quality_report
    vnodes_expected_number=vnodes_expected_number)
  File "/style-analyzer/lookout/style/format/benchmarks/quality_report.py", line 137, in measure_quality
    bblfsh=bblfsh, config_json=config)
  File "/lookout-sdk-ml/lookout/core/helpers/analyzer_context_manager.py", line 87, in review
    log_level=log_level, config_json=config_json)
  File "/lookout-sdk-ml/lookout/core/helpers/server.py", line 101, in review
    return self._run("review", fr, to, port, git_dir, bblfsh, log_level, config_json)
  File "/lookout-sdk-ml/lookout/core/helpers/server.py", line 131, in _run
    return subprocess.run(command, stdout=subprocess.PIPE, stderr=subprocess.PIPE, check=True)
  File "/usr/lib/python3.6/subprocess.py", line 418, in run
    output=stdout, stderr=stderr)
subprocess.CalledProcessError: Command '['/tmp/lookout-sdk-ml/lookout-sdk-v0.7.0', 'review', 'ipv4://localhost:19508', '--from', '133b96a2ff463dda71febbdae434057271e025ed', '--to', '6790c080c641ef2b44e663800e1794fae180977a', '--git-dir', '/tmp/top-repos-quality-repos-mpt4k2lj/handlebars.js.git', '--log-format', 'json', '--log-level', 'warning', '--config-json', '{"style.format.analyzer.FormatAnalyzer": {"aggregate": true}}']' returned non-zero exit status 1.
--------------------
Failed to process https://github.com/verlok/vanilla-lazyload.git repo
Traceback (most recent call last):
  File "/style-analyzer/lookout/style/format/benchmarks/quality_report.py", line 312, in generate_quality_report
    vnodes_expected_number=vnodes_expected_number)
  File "/style-analyzer/lookout/style/format/benchmarks/quality_report.py", line 137, in measure_quality
    bblfsh=bblfsh, config_json=config)
  File "/lookout-sdk-ml/lookout/core/helpers/analyzer_context_manager.py", line 87, in review
    log_level=log_level, config_json=config_json)
  File "/lookout-sdk-ml/lookout/core/helpers/server.py", line 101, in review
    return self._run("review", fr, to, port, git_dir, bblfsh, log_level, config_json)
  File "/lookout-sdk-ml/lookout/core/helpers/server.py", line 131, in _run
    return subprocess.run(command, stdout=subprocess.PIPE, stderr=subprocess.PIPE, check=True)
  File "/usr/lib/python3.6/subprocess.py", line 418, in run
    output=stdout, stderr=stderr)
subprocess.CalledProcessError: Command '['/tmp/lookout-sdk-ml/lookout-sdk-v0.7.0', 'review', 'ipv4://localhost:19508', '--from', 'd675f324445991064490c9a728c70176accac500', '--to', '7b2d8b26bde0a6e03ed411b83f80c62b491fc81d', '--git-dir', '/tmp/top-repos-quality-repos-ngz7drmi/vanilla-lazyload.git', '--log-format', 'json', '--log-level', 'warning', '--config-json', '{"style.format.analyzer.FormatAnalyzer": {"aggregate": true}}']' returned non-zero exit status 1.
--------------------
Failed to process https://github.com/tygs/0bin.git repo
Traceback (most recent call last):
  File "/style-analyzer/lookout/style/format/benchmarks/quality_report.py", line 312, in generate_quality_report
    vnodes_expected_number=vnodes_expected_number)
  File "/style-analyzer/lookout/style/format/benchmarks/quality_report.py", line 137, in measure_quality
    bblfsh=bblfsh, config_json=config)
  File "/lookout-sdk-ml/lookout/core/helpers/analyzer_context_manager.py", line 87, in review
    log_level=log_level, config_json=config_json)
  File "/lookout-sdk-ml/lookout/core/helpers/server.py", line 101, in review
    return self._run("review", fr, to, port, git_dir, bblfsh, log_level, config_json)
  File "/lookout-sdk-ml/lookout/core/helpers/server.py", line 131, in _run
    return subprocess.run(command, stdout=subprocess.PIPE, stderr=subprocess.PIPE, check=True)
  File "/usr/lib/python3.6/subprocess.py", line 418, in run
    output=stdout, stderr=stderr)
subprocess.CalledProcessError: Command '['/tmp/lookout-sdk-ml/lookout-sdk-v0.7.0', 'review', 'ipv4://localhost:19508', '--from', 'd753f92207c4cb7b2e3b8f73350b3323f1b34700', '--to', 'c65d5c4d090d385eb5c40df8e0001af9267f3b4b', '--git-dir', '/tmp/top-repos-quality-repos-mzkyuxxz/0bin.git', '--log-format', 'json', '--log-level', 'warning', '--config-json', '{"style.format.analyzer.FormatAnalyzer": {"aggregate": true}}']' returned non-zero exit status 1.
--------------------
Failed to process https://github.com/adrianhajdin/project_corona_tracker.git repo
Traceback (most recent call last):
  File "/style-analyzer/lookout/style/format/benchmarks/quality_report.py", line 312, in generate_quality_report
    vnodes_expected_number=vnodes_expected_number)
  File "/style-analyzer/lookout/style/format/benchmarks/quality_report.py", line 137, in measure_quality
    bblfsh=bblfsh, config_json=config)
  File "/lookout-sdk-ml/lookout/core/helpers/analyzer_context_manager.py", line 87, in review
    log_level=log_level, config_json=config_json)
  File "/lookout-sdk-ml/lookout/core/helpers/server.py", line 101, in review
    return self._run("review", fr, to, port, git_dir, bblfsh, log_level, config_json)
  File "/lookout-sdk-ml/lookout/core/helpers/server.py", line 131, in _run
    return subprocess.run(command, stdout=subprocess.PIPE, stderr=subprocess.PIPE, check=True)
  File "/usr/lib/python3.6/subprocess.py", line 418, in run
    output=stdout, stderr=stderr)
subprocess.CalledProcessError: Command '['/tmp/lookout-sdk-ml/lookout-sdk-v0.7.0', 'review', 'ipv4://localhost:19508', '--from', '262e0f965acd5ed7bc4fc48f2fc5c451f2914287', '--to', '2c8d4ca81f784dea7a92ba1402d9575de8dc3567', '--git-dir', '/tmp/top-repos-quality-repos-mkcc90wq/project_corona_tracker.git', '--log-format', 'json', '--log-level', 'warning', '--config-json', '{"style.format.analyzer.FormatAnalyzer": {"aggregate": true}}']' returned non-zero exit status 1.
--------------------
Failed to process https://github.com/78/ssbc.git repo
Traceback (most recent call last):
  File "/style-analyzer/lookout/style/format/benchmarks/quality_report.py", line 312, in generate_quality_report
    vnodes_expected_number=vnodes_expected_number)
  File "/style-analyzer/lookout/style/format/benchmarks/quality_report.py", line 137, in measure_quality
    bblfsh=bblfsh, config_json=config)
  File "/lookout-sdk-ml/lookout/core/helpers/analyzer_context_manager.py", line 87, in review
    log_level=log_level, config_json=config_json)
  File "/lookout-sdk-ml/lookout/core/helpers/server.py", line 101, in review
    return self._run("review", fr, to, port, git_dir, bblfsh, log_level, config_json)
  File "/lookout-sdk-ml/lookout/core/helpers/server.py", line 131, in _run
    return subprocess.run(command, stdout=subprocess.PIPE, stderr=subprocess.PIPE, check=True)
  File "/usr/lib/python3.6/subprocess.py", line 418, in run
    output=stdout, stderr=stderr)
subprocess.CalledProcessError: Command '['/tmp/lookout-sdk-ml/lookout-sdk-v0.7.0', 'review', 'ipv4://localhost:19508', '--from', 'd8ebbe3603e6e6ada50c77d3d0efde003ca0b8ef', '--to', '09a64ec201bf974add80db5408237d57fffa9135', '--git-dir', '/tmp/top-repos-quality-repos-wz00pjgf/ssbc.git', '--log-format', 'json', '--log-level', 'warning', '--config-json', '{"style.format.analyzer.FormatAnalyzer": {"aggregate": true}}']' returned non-zero exit status 1.
--------------------
Failed to process https://github.com/karlhadwen/netflix.git repo
Traceback (most recent call last):
  File "/style-analyzer/lookout/style/format/benchmarks/quality_report.py", line 312, in generate_quality_report
    vnodes_expected_number=vnodes_expected_number)
  File "/style-analyzer/lookout/style/format/benchmarks/quality_report.py", line 137, in measure_quality
    bblfsh=bblfsh, config_json=config)
  File "/lookout-sdk-ml/lookout/core/helpers/analyzer_context_manager.py", line 87, in review
    log_level=log_level, config_json=config_json)
  File "/lookout-sdk-ml/lookout/core/helpers/server.py", line 101, in review
    return self._run("review", fr, to, port, git_dir, bblfsh, log_level, config_json)
  File "/lookout-sdk-ml/lookout/core/helpers/server.py", line 131, in _run
    return subprocess.run(command, stdout=subprocess.PIPE, stderr=subprocess.PIPE, check=True)
  File "/usr/lib/python3.6/subprocess.py", line 418, in run
    output=stdout, stderr=stderr)
subprocess.CalledProcessError: Command '['/tmp/lookout-sdk-ml/lookout-sdk-v0.7.0', 'review', 'ipv4://localhost:19508', '--from', '35d6677f2e7cd7489e61799b3258bf348924e3ce', '--to', '54ead17f6b8a240b4ab0d2eeff9d1c66c0a6c206', '--git-dir', '/tmp/top-repos-quality-repos-spje2jey/netflix.git', '--log-format', 'json', '--log-level', 'warning', '--config-json', '{"style.format.analyzer.FormatAnalyzer": {"aggregate": true}}']' returned non-zero exit status 1.
--------------------
Failed to process https://github.com/codeceptjs/codeceptjs.git repo
Traceback (most recent call last):
  File "/style-analyzer/lookout/style/format/benchmarks/quality_report.py", line 312, in generate_quality_report
    vnodes_expected_number=vnodes_expected_number)
  File "/style-analyzer/lookout/style/format/benchmarks/quality_report.py", line 137, in measure_quality
    bblfsh=bblfsh, config_json=config)
  File "/lookout-sdk-ml/lookout/core/helpers/analyzer_context_manager.py", line 87, in review
    log_level=log_level, config_json=config_json)
  File "/lookout-sdk-ml/lookout/core/helpers/server.py", line 101, in review
    return self._run("review", fr, to, port, git_dir, bblfsh, log_level, config_json)
  File "/lookout-sdk-ml/lookout/core/helpers/server.py", line 131, in _run
    return subprocess.run(command, stdout=subprocess.PIPE, stderr=subprocess.PIPE, check=True)
  File "/usr/lib/python3.6/subprocess.py", line 418, in run
    output=stdout, stderr=stderr)
subprocess.CalledProcessError: Command '['/tmp/lookout-sdk-ml/lookout-sdk-v0.7.0', 'review', 'ipv4://localhost:19508', '--from', '5164f0090748d2eca00c152d82a55338ac1e21ec', '--to', '42717c09173fdf8276166c7918b0bbd5c9f1055a', '--git-dir', '/tmp/top-repos-quality-repos-ocgv6dbf/codeceptjs.git', '--log-format', 'json', '--log-level', 'warning', '--config-json', '{"style.format.analyzer.FormatAnalyzer": {"aggregate": true}}']' returned non-zero exit status 1.
--------------------
Failed to process https://github.com/lanistor/react-keeper.git repo
Traceback (most recent call last):
  File "/style-analyzer/lookout/style/format/benchmarks/quality_report.py", line 312, in generate_quality_report
    vnodes_expected_number=vnodes_expected_number)
  File "/style-analyzer/lookout/style/format/benchmarks/quality_report.py", line 137, in measure_quality
    bblfsh=bblfsh, config_json=config)
  File "/lookout-sdk-ml/lookout/core/helpers/analyzer_context_manager.py", line 87, in review
    log_level=log_level, config_json=config_json)
  File "/lookout-sdk-ml/lookout/core/helpers/server.py", line 101, in review
    return self._run("review", fr, to, port, git_dir, bblfsh, log_level, config_json)
  File "/lookout-sdk-ml/lookout/core/helpers/server.py", line 131, in _run
    return subprocess.run(command, stdout=subprocess.PIPE, stderr=subprocess.PIPE, check=True)
  File "/usr/lib/python3.6/subprocess.py", line 418, in run
    output=stdout, stderr=stderr)
subprocess.CalledProcessError: Command '['/tmp/lookout-sdk-ml/lookout-sdk-v0.7.0', 'review', 'ipv4://localhost:19508', '--from', '3fd1eeecdcd7a97077f50dffaf8674e72819daac', '--to', 'e2d9a62e06d79744b48f11875be862921aec0819', '--git-dir', '/tmp/top-repos-quality-repos-y1_x_gw9/react-keeper.git', '--log-format', 'json', '--log-level', 'warning', '--config-json', '{"style.format.analyzer.FormatAnalyzer": {"aggregate": true}}']' returned non-zero exit status 1.
--------------------
Failed to process https://github.com/atom/markdown-preview.git repo
Traceback (most recent call last):
  File "/style-analyzer/lookout/style/format/benchmarks/quality_report.py", line 312, in generate_quality_report
    vnodes_expected_number=vnodes_expected_number)
  File "/style-analyzer/lookout/style/format/benchmarks/quality_report.py", line 137, in measure_quality
    bblfsh=bblfsh, config_json=config)
  File "/lookout-sdk-ml/lookout/core/helpers/analyzer_context_manager.py", line 87, in review
    log_level=log_level, config_json=config_json)
  File "/lookout-sdk-ml/lookout/core/helpers/server.py", line 101, in review
    return self._run("review", fr, to, port, git_dir, bblfsh, log_level, config_json)
  File "/lookout-sdk-ml/lookout/core/helpers/server.py", line 131, in _run
    return subprocess.run(command, stdout=subprocess.PIPE, stderr=subprocess.PIPE, check=True)
  File "/usr/lib/python3.6/subprocess.py", line 418, in run
    output=stdout, stderr=stderr)
subprocess.CalledProcessError: Command '['/tmp/lookout-sdk-ml/lookout-sdk-v0.7.0', 'review', 'ipv4://localhost:19508', '--from', '9c0a9f54f274c990c06bb40c37c7dd2a36f524b2', '--to', '236bdb9d3232a9819ba5d0407f354264ad3223fa', '--git-dir', '/tmp/top-repos-quality-repos-2rct20gz/markdown-preview.git', '--log-format', 'json', '--log-level', 'warning', '--config-json', '{"style.format.analyzer.FormatAnalyzer": {"aggregate": true}}']' returned non-zero exit status 1.
--------------------
Failed to process https://github.com/mechio/takana.git repo
Traceback (most recent call last):
  File "/style-analyzer/lookout/style/format/benchmarks/quality_report.py", line 312, in generate_quality_report
    vnodes_expected_number=vnodes_expected_number)
  File "/style-analyzer/lookout/style/format/benchmarks/quality_report.py", line 137, in measure_quality
    bblfsh=bblfsh, config_json=config)
  File "/lookout-sdk-ml/lookout/core/helpers/analyzer_context_manager.py", line 87, in review
    log_level=log_level, config_json=config_json)
  File "/lookout-sdk-ml/lookout/core/helpers/server.py", line 101, in review
    return self._run("review", fr, to, port, git_dir, bblfsh, log_level, config_json)
  File "/lookout-sdk-ml/lookout/core/helpers/server.py", line 131, in _run
    return subprocess.run(command, stdout=subprocess.PIPE, stderr=subprocess.PIPE, check=True)
  File "/usr/lib/python3.6/subprocess.py", line 418, in run
    output=stdout, stderr=stderr)
subprocess.CalledProcessError: Command '['/tmp/lookout-sdk-ml/lookout-sdk-v0.7.0', 'review', 'ipv4://localhost:3030', '--from', 'a0cce72b5702842229358f6af7934e31875a659c', '--to', '3e274d5990392590ce44b00f1c0acd680f98cf7b', '--git-dir', '/tmp/top-repos-quality-repos-vqif6dm1/takana.git', '--log-format', 'json', '--log-level', 'warning', '--config-json', '{"style.format.analyzer.FormatAnalyzer": {"aggregate": true}}']' returned non-zero exit status 1.
--------------------
Failed to process https://github.com/kickscondor/fraidycat.git repo
Traceback (most recent call last):
  File "/style-analyzer/lookout/style/format/benchmarks/quality_report.py", line 312, in generate_quality_report
    vnodes_expected_number=vnodes_expected_number)
  File "/style-analyzer/lookout/style/format/benchmarks/quality_report.py", line 137, in measure_quality
    bblfsh=bblfsh, config_json=config)
  File "/lookout-sdk-ml/lookout/core/helpers/analyzer_context_manager.py", line 87, in review
    log_level=log_level, config_json=config_json)
  File "/lookout-sdk-ml/lookout/core/helpers/server.py", line 101, in review
    return self._run("review", fr, to, port, git_dir, bblfsh, log_level, config_json)
  File "/lookout-sdk-ml/lookout/core/helpers/server.py", line 131, in _run
    return subprocess.run(command, stdout=subprocess.PIPE, stderr=subprocess.PIPE, check=True)
  File "/usr/lib/python3.6/subprocess.py", line 418, in run
    output=stdout, stderr=stderr)
subprocess.CalledProcessError: Command '['/tmp/lookout-sdk-ml/lookout-sdk-v0.7.0', 'review', 'ipv4://localhost:3030', '--from', '664ab8cee487b03d9915f3308715958703d40bcd', '--to', 'a5480cfaf37953463598892f977ce53069a40a69', '--git-dir', '/tmp/top-repos-quality-repos-lkrgpnb1/fraidycat.git', '--log-format', 'json', '--log-level', 'warning', '--config-json', '{"style.format.analyzer.FormatAnalyzer": {"aggregate": true}}']' returned non-zero exit status 1.
--------------------
Failed to process https://github.com/apachecn/apachecn-algo-zh.git repo
Traceback (most recent call last):
  File "/style-analyzer/lookout/style/format/benchmarks/quality_report.py", line 312, in generate_quality_report
    vnodes_expected_number=vnodes_expected_number)
  File "/style-analyzer/lookout/style/format/benchmarks/quality_report.py", line 137, in measure_quality
    bblfsh=bblfsh, config_json=config)
  File "/lookout-sdk-ml/lookout/core/helpers/analyzer_context_manager.py", line 87, in review
    log_level=log_level, config_json=config_json)
  File "/lookout-sdk-ml/lookout/core/helpers/server.py", line 101, in review
    return self._run("review", fr, to, port, git_dir, bblfsh, log_level, config_json)
  File "/lookout-sdk-ml/lookout/core/helpers/server.py", line 131, in _run
    return subprocess.run(command, stdout=subprocess.PIPE, stderr=subprocess.PIPE, check=True)
  File "/usr/lib/python3.6/subprocess.py", line 418, in run
    output=stdout, stderr=stderr)
subprocess.CalledProcessError: Command '['/tmp/lookout-sdk-ml/lookout-sdk-v0.7.0', 'review', 'ipv4://localhost:3030', '--from', '8c0bee04fc7ca4e22e50023b76620c1458e6b8ae', '--to', '71862d95dd7e1e34c8e193b3ebf1063172a2cbf0', '--git-dir', '/tmp/top-repos-quality-repos-o3lgq7sl/apachecn-algo-zh.git', '--log-format', 'json', '--log-level', 'warning', '--config-json', '{"style.format.analyzer.FormatAnalyzer": {"aggregate": true}}']' returned non-zero exit status 1.
--------------------
Failed to process https://github.com/shaunlebron/parinfer.git repo
Traceback (most recent call last):
  File "/style-analyzer/lookout/style/format/benchmarks/quality_report.py", line 312, in generate_quality_report
    vnodes_expected_number=vnodes_expected_number)
  File "/style-analyzer/lookout/style/format/benchmarks/quality_report.py", line 137, in measure_quality
    bblfsh=bblfsh, config_json=config)
  File "/lookout-sdk-ml/lookout/core/helpers/analyzer_context_manager.py", line 87, in review
    log_level=log_level, config_json=config_json)
  File "/lookout-sdk-ml/lookout/core/helpers/server.py", line 101, in review
    return self._run("review", fr, to, port, git_dir, bblfsh, log_level, config_json)
  File "/lookout-sdk-ml/lookout/core/helpers/server.py", line 131, in _run
    return subprocess.run(command, stdout=subprocess.PIPE, stderr=subprocess.PIPE, check=True)
  File "/usr/lib/python3.6/subprocess.py", line 418, in run
    output=stdout, stderr=stderr)
subprocess.CalledProcessError: Command '['/tmp/lookout-sdk-ml/lookout-sdk-v0.7.0', 'review', 'ipv4://localhost:3030', '--from', 'f2e3320bcde6a95f4fb653386ef9c9c22ed3420f', '--to', '41c74d03534a5adbdcb7430fb666899e8dbf746d', '--git-dir', '/tmp/top-repos-quality-repos-7rl4h7wj/parinfer.git', '--log-format', 'json', '--log-level', 'warning', '--config-json', '{"style.format.analyzer.FormatAnalyzer": {"aggregate": true}}']' returned non-zero exit status 1.
--------------------
Failed to process https://github.com/lukeed/uvu.git repo
Traceback (most recent call last):
  File "/style-analyzer/lookout/style/format/benchmarks/quality_report.py", line 312, in generate_quality_report
    vnodes_expected_number=vnodes_expected_number)
  File "/style-analyzer/lookout/style/format/benchmarks/quality_report.py", line 137, in measure_quality
    bblfsh=bblfsh, config_json=config)
  File "/lookout-sdk-ml/lookout/core/helpers/analyzer_context_manager.py", line 87, in review
    log_level=log_level, config_json=config_json)
  File "/lookout-sdk-ml/lookout/core/helpers/server.py", line 101, in review
    return self._run("review", fr, to, port, git_dir, bblfsh, log_level, config_json)
  File "/lookout-sdk-ml/lookout/core/helpers/server.py", line 131, in _run
    return subprocess.run(command, stdout=subprocess.PIPE, stderr=subprocess.PIPE, check=True)
  File "/usr/lib/python3.6/subprocess.py", line 418, in run
    output=stdout, stderr=stderr)
subprocess.CalledProcessError: Command '['/tmp/lookout-sdk-ml/lookout-sdk-v0.7.0', 'review', 'ipv4://localhost:3030', '--from', '988d9290adef593aaf3ee169868b9fcef0d9d0f3', '--to', 'd56753ec20928da1c22ff093cb07ce3c67613706', '--git-dir', '/tmp/top-repos-quality-repos-9qv00jr3/uvu.git', '--log-format', 'json', '--log-level', 'warning', '--config-json', '{"style.format.analyzer.FormatAnalyzer": {"aggregate": true}}']' returned non-zero exit status 1.
--------------------
Failed to process https://github.com/affinelayer/pix2pix-tensorflow.git repo
Traceback (most recent call last):
  File "/style-analyzer/lookout/style/format/benchmarks/quality_report.py", line 312, in generate_quality_report
    vnodes_expected_number=vnodes_expected_number)
  File "/style-analyzer/lookout/style/format/benchmarks/quality_report.py", line 137, in measure_quality
    bblfsh=bblfsh, config_json=config)
  File "/lookout-sdk-ml/lookout/core/helpers/analyzer_context_manager.py", line 87, in review
    log_level=log_level, config_json=config_json)
  File "/lookout-sdk-ml/lookout/core/helpers/server.py", line 101, in review
    return self._run("review", fr, to, port, git_dir, bblfsh, log_level, config_json)
  File "/lookout-sdk-ml/lookout/core/helpers/server.py", line 131, in _run
    return subprocess.run(command, stdout=subprocess.PIPE, stderr=subprocess.PIPE, check=True)
  File "/usr/lib/python3.6/subprocess.py", line 418, in run
    output=stdout, stderr=stderr)
subprocess.CalledProcessError: Command '['/tmp/lookout-sdk-ml/lookout-sdk-v0.7.0', 'review', 'ipv4://localhost:3030', '--from', '5c761a294e0ddd5a43fa2bb3de110f46e7a8f30a', '--to', '0f2174424356162920fc25067e63db2bcf19f4e7', '--git-dir', '/tmp/top-repos-quality-repos-5zv0f2ea/pix2pix-tensorflow.git', '--log-format', 'json', '--log-level', 'warning', '--config-json', '{"style.format.analyzer.FormatAnalyzer": {"aggregate": true}}']' returned non-zero exit status 1.
--------------------
Failed to process https://github.com/prettier/prettier-eslint.git repo
Traceback (most recent call last):
  File "/style-analyzer/lookout/style/format/benchmarks/quality_report.py", line 312, in generate_quality_report
    vnodes_expected_number=vnodes_expected_number)
  File "/style-analyzer/lookout/style/format/benchmarks/quality_report.py", line 137, in measure_quality
    bblfsh=bblfsh, config_json=config)
  File "/lookout-sdk-ml/lookout/core/helpers/analyzer_context_manager.py", line 87, in review
    log_level=log_level, config_json=config_json)
  File "/lookout-sdk-ml/lookout/core/helpers/server.py", line 101, in review
    return self._run("review", fr, to, port, git_dir, bblfsh, log_level, config_json)
  File "/lookout-sdk-ml/lookout/core/helpers/server.py", line 131, in _run
    return subprocess.run(command, stdout=subprocess.PIPE, stderr=subprocess.PIPE, check=True)
  File "/usr/lib/python3.6/subprocess.py", line 418, in run
    output=stdout, stderr=stderr)
subprocess.CalledProcessError: Command '['/tmp/lookout-sdk-ml/lookout-sdk-v0.7.0', 'review', 'ipv4://localhost:3030', '--from', 'db6f7cb0abadf1bef27ab4bdd058bfa37b7af361', '--to', 'c62769ef430749fb9650c7e1d05f5cf7442a48a2', '--git-dir', '/tmp/top-repos-quality-repos-_e8zro1q/prettier-eslint.git', '--log-format', 'json', '--log-level', 'warning', '--config-json', '{"style.format.analyzer.FormatAnalyzer": {"aggregate": true}}']' returned non-zero exit status 1.
--------------------
Failed to process https://github.com/mandatoryprogrammer/cursedchrome.git repo
Traceback (most recent call last):
  File "/style-analyzer/lookout/style/format/benchmarks/quality_report.py", line 312, in generate_quality_report
    vnodes_expected_number=vnodes_expected_number)
  File "/style-analyzer/lookout/style/format/benchmarks/quality_report.py", line 137, in measure_quality
    bblfsh=bblfsh, config_json=config)
  File "/lookout-sdk-ml/lookout/core/helpers/analyzer_context_manager.py", line 87, in review
    log_level=log_level, config_json=config_json)
  File "/lookout-sdk-ml/lookout/core/helpers/server.py", line 101, in review
    return self._run("review", fr, to, port, git_dir, bblfsh, log_level, config_json)
  File "/lookout-sdk-ml/lookout/core/helpers/server.py", line 131, in _run
    return subprocess.run(command, stdout=subprocess.PIPE, stderr=subprocess.PIPE, check=True)
  File "/usr/lib/python3.6/subprocess.py", line 418, in run
    output=stdout, stderr=stderr)
subprocess.CalledProcessError: Command '['/tmp/lookout-sdk-ml/lookout-sdk-v0.7.0', 'review', 'ipv4://localhost:3030', '--from', 'f7c0dd87d73238f2ef3d631d6db90e5f490cebe0', '--to', 'f18eaee6e3aee866b801235e836d9576aff008de', '--git-dir', '/tmp/top-repos-quality-repos-snrimhg8/cursedchrome.git', '--log-format', 'json', '--log-level', 'warning', '--config-json', '{"style.format.analyzer.FormatAnalyzer": {"aggregate": true}}']' returned non-zero exit status 1.
--------------------
Failed to process https://github.com/disease-sh/api.git repo
Traceback (most recent call last):
  File "/style-analyzer/lookout/style/format/benchmarks/quality_report.py", line 312, in generate_quality_report
    vnodes_expected_number=vnodes_expected_number)
  File "/style-analyzer/lookout/style/format/benchmarks/quality_report.py", line 137, in measure_quality
    bblfsh=bblfsh, config_json=config)
  File "/lookout-sdk-ml/lookout/core/helpers/analyzer_context_manager.py", line 87, in review
    log_level=log_level, config_json=config_json)
  File "/lookout-sdk-ml/lookout/core/helpers/server.py", line 101, in review
    return self._run("review", fr, to, port, git_dir, bblfsh, log_level, config_json)
  File "/lookout-sdk-ml/lookout/core/helpers/server.py", line 131, in _run
    return subprocess.run(command, stdout=subprocess.PIPE, stderr=subprocess.PIPE, check=True)
  File "/usr/lib/python3.6/subprocess.py", line 418, in run
    output=stdout, stderr=stderr)
subprocess.CalledProcessError: Command '['/tmp/lookout-sdk-ml/lookout-sdk-v0.7.0', 'review', 'ipv4://localhost:3030', '--from', 'da39023402eaea84409f7a495eca9fd21935b8c3', '--to', '3ba2eac0e7c9093852bdd3400c7f2581cd74ac9e', '--git-dir', '/tmp/top-repos-quality-repos-6mwmxsae/api.git', '--log-format', 'json', '--log-level', 'warning', '--config-json', '{"style.format.analyzer.FormatAnalyzer": {"aggregate": true}}']' returned non-zero exit status 1.
--------------------
Failed to process https://github.com/coffe1891/frontend-hard-mode-interview.git repo
Traceback (most recent call last):
  File "/style-analyzer/lookout/style/format/benchmarks/quality_report.py", line 312, in generate_quality_report
    vnodes_expected_number=vnodes_expected_number)
  File "/style-analyzer/lookout/style/format/benchmarks/quality_report.py", line 137, in measure_quality
    bblfsh=bblfsh, config_json=config)
  File "/lookout-sdk-ml/lookout/core/helpers/analyzer_context_manager.py", line 87, in review
    log_level=log_level, config_json=config_json)
  File "/lookout-sdk-ml/lookout/core/helpers/server.py", line 101, in review
    return self._run("review", fr, to, port, git_dir, bblfsh, log_level, config_json)
  File "/lookout-sdk-ml/lookout/core/helpers/server.py", line 131, in _run
    return subprocess.run(command, stdout=subprocess.PIPE, stderr=subprocess.PIPE, check=True)
  File "/usr/lib/python3.6/subprocess.py", line 418, in run
    output=stdout, stderr=stderr)
subprocess.CalledProcessError: Command '['/tmp/lookout-sdk-ml/lookout-sdk-v0.7.0', 'review', 'ipv4://localhost:3030', '--from', '6d11051ec005ed2fc897b8028e1ddb5473618c81', '--to', 'ffb7ff24d792522f8294fc81abe3ac6381053c1e', '--git-dir', '/tmp/top-repos-quality-repos-7ignphlb/frontend-hard-mode-interview.git', '--log-format', 'json', '--log-level', 'warning', '--config-json', '{"style.format.analyzer.FormatAnalyzer": {"aggregate": true}}']' returned non-zero exit status 1.
--------------------
Failed to process https://github.com/electerious/ackee.git repo
Traceback (most recent call last):
  File "/style-analyzer/lookout/style/format/benchmarks/quality_report.py", line 312, in generate_quality_report
    vnodes_expected_number=vnodes_expected_number)
  File "/style-analyzer/lookout/style/format/benchmarks/quality_report.py", line 137, in measure_quality
    bblfsh=bblfsh, config_json=config)
  File "/lookout-sdk-ml/lookout/core/helpers/analyzer_context_manager.py", line 87, in review
    log_level=log_level, config_json=config_json)
  File "/lookout-sdk-ml/lookout/core/helpers/server.py", line 101, in review
    return self._run("review", fr, to, port, git_dir, bblfsh, log_level, config_json)
  File "/lookout-sdk-ml/lookout/core/helpers/server.py", line 131, in _run
    return subprocess.run(command, stdout=subprocess.PIPE, stderr=subprocess.PIPE, check=True)
  File "/usr/lib/python3.6/subprocess.py", line 418, in run
    output=stdout, stderr=stderr)
subprocess.CalledProcessError: Command '['/tmp/lookout-sdk-ml/lookout-sdk-v0.7.0', 'review', 'ipv4://localhost:3030', '--from', '1710fcd013482a13faeb449fabd2728edf50adfb', '--to', '9a6e51d337ab7c9affdc6752e1acbe9405d0f633', '--git-dir', '/tmp/top-repos-quality-repos-vg220wed/ackee.git', '--log-format', 'json', '--log-level', 'warning', '--config-json', '{"style.format.analyzer.FormatAnalyzer": {"aggregate": true}}']' returned non-zero exit status 1.
--------------------
Failed to process https://github.com/ines/termynal.git repo
Traceback (most recent call last):
  File "/style-analyzer/lookout/style/format/benchmarks/quality_report.py", line 312, in generate_quality_report
    vnodes_expected_number=vnodes_expected_number)
  File "/style-analyzer/lookout/style/format/benchmarks/quality_report.py", line 137, in measure_quality
    bblfsh=bblfsh, config_json=config)
  File "/lookout-sdk-ml/lookout/core/helpers/analyzer_context_manager.py", line 87, in review
    log_level=log_level, config_json=config_json)
  File "/lookout-sdk-ml/lookout/core/helpers/server.py", line 101, in review
    return self._run("review", fr, to, port, git_dir, bblfsh, log_level, config_json)
  File "/lookout-sdk-ml/lookout/core/helpers/server.py", line 131, in _run
    return subprocess.run(command, stdout=subprocess.PIPE, stderr=subprocess.PIPE, check=True)
  File "/usr/lib/python3.6/subprocess.py", line 418, in run
    output=stdout, stderr=stderr)
subprocess.CalledProcessError: Command '['/tmp/lookout-sdk-ml/lookout-sdk-v0.7.0', 'review', 'ipv4://localhost:3030', '--from', '39389bf5a3cf7ad5cceda733ea6a1c7ed6e9d532', '--to', '9b301892db6f8d403abfce7adf65888dffed72ea', '--git-dir', '/tmp/top-repos-quality-repos-t32phqx4/termynal.git', '--log-format', 'json', '--log-level', 'warning', '--config-json', '{"style.format.analyzer.FormatAnalyzer": {"aggregate": true}}']' returned non-zero exit status 1.
--------------------
Failed to process https://github.com/wordpress-mobile/wordpress-editor-ios.git repo
Traceback (most recent call last):
  File "/style-analyzer/lookout/style/format/benchmarks/quality_report.py", line 312, in generate_quality_report
    vnodes_expected_number=vnodes_expected_number)
  File "/style-analyzer/lookout/style/format/benchmarks/quality_report.py", line 137, in measure_quality
    bblfsh=bblfsh, config_json=config)
  File "/lookout-sdk-ml/lookout/core/helpers/analyzer_context_manager.py", line 87, in review
    log_level=log_level, config_json=config_json)
  File "/lookout-sdk-ml/lookout/core/helpers/server.py", line 101, in review
    return self._run("review", fr, to, port, git_dir, bblfsh, log_level, config_json)
  File "/lookout-sdk-ml/lookout/core/helpers/server.py", line 131, in _run
    return subprocess.run(command, stdout=subprocess.PIPE, stderr=subprocess.PIPE, check=True)
  File "/usr/lib/python3.6/subprocess.py", line 418, in run
    output=stdout, stderr=stderr)
subprocess.CalledProcessError: Command '['/tmp/lookout-sdk-ml/lookout-sdk-v0.7.0', 'review', 'ipv4://localhost:3030', '--from', '18115b109e90e91fb41fc7c062c84dee23f42ef7', '--to', 'b56b59e8f76b6eaf0bb378b487d7ec38db5a407e', '--git-dir', '/tmp/top-repos-quality-repos-icy58wms/wordpress-editor-ios.git', '--log-format', 'json', '--log-level', 'warning', '--config-json', '{"style.format.analyzer.FormatAnalyzer": {"aggregate": true}}']' returned non-zero exit status 1.
--------------------
Failed to process https://github.com/alexmojaki/birdseye.git repo
Traceback (most recent call last):
  File "/style-analyzer/lookout/style/format/benchmarks/quality_report.py", line 312, in generate_quality_report
    vnodes_expected_number=vnodes_expected_number)
  File "/style-analyzer/lookout/style/format/benchmarks/quality_report.py", line 137, in measure_quality
    bblfsh=bblfsh, config_json=config)
  File "/lookout-sdk-ml/lookout/core/helpers/analyzer_context_manager.py", line 87, in review
    log_level=log_level, config_json=config_json)
  File "/lookout-sdk-ml/lookout/core/helpers/server.py", line 101, in review
    return self._run("review", fr, to, port, git_dir, bblfsh, log_level, config_json)
  File "/lookout-sdk-ml/lookout/core/helpers/server.py", line 131, in _run
    return subprocess.run(command, stdout=subprocess.PIPE, stderr=subprocess.PIPE, check=True)
  File "/usr/lib/python3.6/subprocess.py", line 418, in run
    output=stdout, stderr=stderr)
subprocess.CalledProcessError: Command '['/tmp/lookout-sdk-ml/lookout-sdk-v0.7.0', 'review', 'ipv4://localhost:3030', '--from', '7038bfe7dcd51cc8a079a9be33688d2b450e1c83', '--to', '0f0e0b40e16584d232587e0cffec41660a158aa0', '--git-dir', '/tmp/top-repos-quality-repos-4ad999c_/birdseye.git', '--log-format', 'json', '--log-level', 'warning', '--config-json', '{"style.format.analyzer.FormatAnalyzer": {"aggregate": true}}']' returned non-zero exit status 1.
--------------------
Failed to process https://github.com/yangshun/tech-interview-handbook.git repo
Traceback (most recent call last):
  File "/style-analyzer/lookout/style/format/benchmarks/quality_report.py", line 312, in generate_quality_report
    vnodes_expected_number=vnodes_expected_number)
  File "/style-analyzer/lookout/style/format/benchmarks/quality_report.py", line 137, in measure_quality
    bblfsh=bblfsh, config_json=config)
  File "/lookout-sdk-ml/lookout/core/helpers/analyzer_context_manager.py", line 87, in review
    log_level=log_level, config_json=config_json)
  File "/lookout-sdk-ml/lookout/core/helpers/server.py", line 101, in review
    return self._run("review", fr, to, port, git_dir, bblfsh, log_level, config_json)
  File "/lookout-sdk-ml/lookout/core/helpers/server.py", line 131, in _run
    return subprocess.run(command, stdout=subprocess.PIPE, stderr=subprocess.PIPE, check=True)
  File "/usr/lib/python3.6/subprocess.py", line 418, in run
    output=stdout, stderr=stderr)
subprocess.CalledProcessError: Command '['/tmp/lookout-sdk-ml/lookout-sdk-v0.7.0', 'review', 'ipv4://localhost:3030', '--from', 'd0458155cf537b6db04da73d0556a0339b3ad26f', '--to', '89318237ccb161a786cc0b5b50a2d9a85b09a9d6', '--git-dir', '/tmp/top-repos-quality-repos-nfcwz2v7/tech-interview-handbook.git', '--log-format', 'json', '--log-level', 'warning', '--config-json', '{"style.format.analyzer.FormatAnalyzer": {"aggregate": true}}']' returned non-zero exit status 1.
--------------------
Failed to process https://github.com/tengbao/vanta.git repo
Traceback (most recent call last):
  File "/style-analyzer/lookout/style/format/benchmarks/quality_report.py", line 312, in generate_quality_report
    vnodes_expected_number=vnodes_expected_number)
  File "/style-analyzer/lookout/style/format/benchmarks/quality_report.py", line 137, in measure_quality
    bblfsh=bblfsh, config_json=config)
  File "/lookout-sdk-ml/lookout/core/helpers/analyzer_context_manager.py", line 87, in review
    log_level=log_level, config_json=config_json)
  File "/lookout-sdk-ml/lookout/core/helpers/server.py", line 101, in review
    return self._run("review", fr, to, port, git_dir, bblfsh, log_level, config_json)
  File "/lookout-sdk-ml/lookout/core/helpers/server.py", line 131, in _run
    return subprocess.run(command, stdout=subprocess.PIPE, stderr=subprocess.PIPE, check=True)
  File "/usr/lib/python3.6/subprocess.py", line 418, in run
    output=stdout, stderr=stderr)
subprocess.CalledProcessError: Command '['/tmp/lookout-sdk-ml/lookout-sdk-v0.7.0', 'review', 'ipv4://localhost:3030', '--from', '9a6e92a53cb5531b72a976c126b78e0ead2991f9', '--to', '2f5cfabfd4388a362b337a9b74783cb96de92b4f', '--git-dir', '/tmp/top-repos-quality-repos-g9n4fq89/vanta.git', '--log-format', 'json', '--log-level', 'warning', '--config-json', '{"style.format.analyzer.FormatAnalyzer": {"aggregate": true}}']' returned non-zero exit status 1.
--------------------
Failed to process https://github.com/enzymejs/enzyme.git repo
Traceback (most recent call last):
  File "/style-analyzer/lookout/style/format/benchmarks/quality_report.py", line 312, in generate_quality_report
    vnodes_expected_number=vnodes_expected_number)
  File "/style-analyzer/lookout/style/format/benchmarks/quality_report.py", line 137, in measure_quality
    bblfsh=bblfsh, config_json=config)
  File "/lookout-sdk-ml/lookout/core/helpers/analyzer_context_manager.py", line 87, in review
    log_level=log_level, config_json=config_json)
  File "/lookout-sdk-ml/lookout/core/helpers/server.py", line 101, in review
    return self._run("review", fr, to, port, git_dir, bblfsh, log_level, config_json)
  File "/lookout-sdk-ml/lookout/core/helpers/server.py", line 131, in _run
    return subprocess.run(command, stdout=subprocess.PIPE, stderr=subprocess.PIPE, check=True)
  File "/usr/lib/python3.6/subprocess.py", line 418, in run
    output=stdout, stderr=stderr)
subprocess.CalledProcessError: Command '['/tmp/lookout-sdk-ml/lookout-sdk-v0.7.0', 'review', 'ipv4://localhost:3030', '--from', '081554e6295164ac88023823e352d06be9fa4e23', '--to', '8c55734eb19a2f7555eb3d695ae11401fa1f9847', '--git-dir', '/tmp/top-repos-quality-repos-j6ma38r4/enzyme.git', '--log-format', 'json', '--log-level', 'warning', '--config-json', '{"style.format.analyzer.FormatAnalyzer": {"aggregate": true}}']' returned non-zero exit status 1.
--------------------
Failed to process https://github.com/mathiasbynens/esrever.git repo
Traceback (most recent call last):
  File "/style-analyzer/lookout/style/format/benchmarks/quality_report.py", line 312, in generate_quality_report
    vnodes_expected_number=vnodes_expected_number)
  File "/style-analyzer/lookout/style/format/benchmarks/quality_report.py", line 137, in measure_quality
    bblfsh=bblfsh, config_json=config)
  File "/lookout-sdk-ml/lookout/core/helpers/analyzer_context_manager.py", line 87, in review
    log_level=log_level, config_json=config_json)
  File "/lookout-sdk-ml/lookout/core/helpers/server.py", line 101, in review
    return self._run("review", fr, to, port, git_dir, bblfsh, log_level, config_json)
  File "/lookout-sdk-ml/lookout/core/helpers/server.py", line 131, in _run
    return subprocess.run(command, stdout=subprocess.PIPE, stderr=subprocess.PIPE, check=True)
  File "/usr/lib/python3.6/subprocess.py", line 418, in run
    output=stdout, stderr=stderr)
subprocess.CalledProcessError: Command '['/tmp/lookout-sdk-ml/lookout-sdk-v0.7.0', 'review', 'ipv4://localhost:3030', '--from', '5d0299c38b66d2be536e4fd0999e5532ac5066c3', '--to', '14b34013dad49106ca08c0e65919f1fc8fea5331', '--git-dir', '/tmp/top-repos-quality-repos-2ro6gc6i/esrever.git', '--log-format', 'json', '--log-level', 'warning', '--config-json', '{"style.format.analyzer.FormatAnalyzer": {"aggregate": true}}']' returned non-zero exit status 1.
--------------------
Failed to process https://github.com/handlebars-lang/handlebars.js.git repo
Traceback (most recent call last):
  File "/style-analyzer/lookout/style/format/benchmarks/quality_report.py", line 312, in generate_quality_report
    vnodes_expected_number=vnodes_expected_number)
  File "/style-analyzer/lookout/style/format/benchmarks/quality_report.py", line 137, in measure_quality
    bblfsh=bblfsh, config_json=config)
  File "/lookout-sdk-ml/lookout/core/helpers/analyzer_context_manager.py", line 87, in review
    log_level=log_level, config_json=config_json)
  File "/lookout-sdk-ml/lookout/core/helpers/server.py", line 101, in review
    return self._run("review", fr, to, port, git_dir, bblfsh, log_level, config_json)
  File "/lookout-sdk-ml/lookout/core/helpers/server.py", line 131, in _run
    return subprocess.run(command, stdout=subprocess.PIPE, stderr=subprocess.PIPE, check=True)
  File "/usr/lib/python3.6/subprocess.py", line 418, in run
    output=stdout, stderr=stderr)
subprocess.CalledProcessError: Command '['/tmp/lookout-sdk-ml/lookout-sdk-v0.7.0', 'review', 'ipv4://localhost:3030', '--from', '133b96a2ff463dda71febbdae434057271e025ed', '--to', '6790c080c641ef2b44e663800e1794fae180977a', '--git-dir', '/tmp/top-repos-quality-repos-zng2nc3u/handlebars.js.git', '--log-format', 'json', '--log-level', 'warning', '--config-json', '{"style.format.analyzer.FormatAnalyzer": {"aggregate": true}}']' returned non-zero exit status 1.
--------------------
Failed to process https://github.com/verlok/vanilla-lazyload.git repo
Traceback (most recent call last):
  File "/style-analyzer/lookout/style/format/benchmarks/quality_report.py", line 312, in generate_quality_report
    vnodes_expected_number=vnodes_expected_number)
  File "/style-analyzer/lookout/style/format/benchmarks/quality_report.py", line 137, in measure_quality
    bblfsh=bblfsh, config_json=config)
  File "/lookout-sdk-ml/lookout/core/helpers/analyzer_context_manager.py", line 87, in review
    log_level=log_level, config_json=config_json)
  File "/lookout-sdk-ml/lookout/core/helpers/server.py", line 101, in review
    return self._run("review", fr, to, port, git_dir, bblfsh, log_level, config_json)
  File "/lookout-sdk-ml/lookout/core/helpers/server.py", line 131, in _run
    return subprocess.run(command, stdout=subprocess.PIPE, stderr=subprocess.PIPE, check=True)
  File "/usr/lib/python3.6/subprocess.py", line 418, in run
    output=stdout, stderr=stderr)
subprocess.CalledProcessError: Command '['/tmp/lookout-sdk-ml/lookout-sdk-v0.7.0', 'review', 'ipv4://localhost:3030', '--from', 'd675f324445991064490c9a728c70176accac500', '--to', '7b2d8b26bde0a6e03ed411b83f80c62b491fc81d', '--git-dir', '/tmp/top-repos-quality-repos-xsy8p2_c/vanilla-lazyload.git', '--log-format', 'json', '--log-level', 'warning', '--config-json', '{"style.format.analyzer.FormatAnalyzer": {"aggregate": true}}']' returned non-zero exit status 1.
--------------------
Failed to process https://github.com/tygs/0bin.git repo
Traceback (most recent call last):
  File "/style-analyzer/lookout/style/format/benchmarks/quality_report.py", line 312, in generate_quality_report
    vnodes_expected_number=vnodes_expected_number)
  File "/style-analyzer/lookout/style/format/benchmarks/quality_report.py", line 137, in measure_quality
    bblfsh=bblfsh, config_json=config)
  File "/lookout-sdk-ml/lookout/core/helpers/analyzer_context_manager.py", line 87, in review
    log_level=log_level, config_json=config_json)
  File "/lookout-sdk-ml/lookout/core/helpers/server.py", line 101, in review
    return self._run("review", fr, to, port, git_dir, bblfsh, log_level, config_json)
  File "/lookout-sdk-ml/lookout/core/helpers/server.py", line 131, in _run
    return subprocess.run(command, stdout=subprocess.PIPE, stderr=subprocess.PIPE, check=True)
  File "/usr/lib/python3.6/subprocess.py", line 418, in run
    output=stdout, stderr=stderr)
subprocess.CalledProcessError: Command '['/tmp/lookout-sdk-ml/lookout-sdk-v0.7.0', 'review', 'ipv4://localhost:3030', '--from', 'd753f92207c4cb7b2e3b8f73350b3323f1b34700', '--to', 'c65d5c4d090d385eb5c40df8e0001af9267f3b4b', '--git-dir', '/tmp/top-repos-quality-repos-sfctqxkn/0bin.git', '--log-format', 'json', '--log-level', 'warning', '--config-json', '{"style.format.analyzer.FormatAnalyzer": {"aggregate": true}}']' returned non-zero exit status 1.
--------------------
Failed to process https://github.com/adrianhajdin/project_corona_tracker.git repo
Traceback (most recent call last):
  File "/style-analyzer/lookout/style/format/benchmarks/quality_report.py", line 312, in generate_quality_report
    vnodes_expected_number=vnodes_expected_number)
  File "/style-analyzer/lookout/style/format/benchmarks/quality_report.py", line 137, in measure_quality
    bblfsh=bblfsh, config_json=config)
  File "/lookout-sdk-ml/lookout/core/helpers/analyzer_context_manager.py", line 87, in review
    log_level=log_level, config_json=config_json)
  File "/lookout-sdk-ml/lookout/core/helpers/server.py", line 101, in review
    return self._run("review", fr, to, port, git_dir, bblfsh, log_level, config_json)
  File "/lookout-sdk-ml/lookout/core/helpers/server.py", line 131, in _run
    return subprocess.run(command, stdout=subprocess.PIPE, stderr=subprocess.PIPE, check=True)
  File "/usr/lib/python3.6/subprocess.py", line 418, in run
    output=stdout, stderr=stderr)
subprocess.CalledProcessError: Command '['/tmp/lookout-sdk-ml/lookout-sdk-v0.7.0', 'review', 'ipv4://localhost:3030', '--from', '262e0f965acd5ed7bc4fc48f2fc5c451f2914287', '--to', '2c8d4ca81f784dea7a92ba1402d9575de8dc3567', '--git-dir', '/tmp/top-repos-quality-repos-ovqo47zo/project_corona_tracker.git', '--log-format', 'json', '--log-level', 'warning', '--config-json', '{"style.format.analyzer.FormatAnalyzer": {"aggregate": true}}']' returned non-zero exit status 1.
--------------------
Failed to process https://github.com/78/ssbc.git repo
Traceback (most recent call last):
  File "/style-analyzer/lookout/style/format/benchmarks/quality_report.py", line 312, in generate_quality_report
    vnodes_expected_number=vnodes_expected_number)
  File "/style-analyzer/lookout/style/format/benchmarks/quality_report.py", line 137, in measure_quality
    bblfsh=bblfsh, config_json=config)
  File "/lookout-sdk-ml/lookout/core/helpers/analyzer_context_manager.py", line 87, in review
    log_level=log_level, config_json=config_json)
  File "/lookout-sdk-ml/lookout/core/helpers/server.py", line 101, in review
    return self._run("review", fr, to, port, git_dir, bblfsh, log_level, config_json)
  File "/lookout-sdk-ml/lookout/core/helpers/server.py", line 131, in _run
    return subprocess.run(command, stdout=subprocess.PIPE, stderr=subprocess.PIPE, check=True)
  File "/usr/lib/python3.6/subprocess.py", line 418, in run
    output=stdout, stderr=stderr)
subprocess.CalledProcessError: Command '['/tmp/lookout-sdk-ml/lookout-sdk-v0.7.0', 'review', 'ipv4://localhost:3030', '--from', 'd8ebbe3603e6e6ada50c77d3d0efde003ca0b8ef', '--to', '09a64ec201bf974add80db5408237d57fffa9135', '--git-dir', '/tmp/top-repos-quality-repos-n1xb54tt/ssbc.git', '--log-format', 'json', '--log-level', 'warning', '--config-json', '{"style.format.analyzer.FormatAnalyzer": {"aggregate": true}}']' returned non-zero exit status 1.
--------------------
Failed to process https://github.com/karlhadwen/netflix.git repo
Traceback (most recent call last):
  File "/style-analyzer/lookout/style/format/benchmarks/quality_report.py", line 312, in generate_quality_report
    vnodes_expected_number=vnodes_expected_number)
  File "/style-analyzer/lookout/style/format/benchmarks/quality_report.py", line 137, in measure_quality
    bblfsh=bblfsh, config_json=config)
  File "/lookout-sdk-ml/lookout/core/helpers/analyzer_context_manager.py", line 87, in review
    log_level=log_level, config_json=config_json)
  File "/lookout-sdk-ml/lookout/core/helpers/server.py", line 101, in review
    return self._run("review", fr, to, port, git_dir, bblfsh, log_level, config_json)
  File "/lookout-sdk-ml/lookout/core/helpers/server.py", line 131, in _run
    return subprocess.run(command, stdout=subprocess.PIPE, stderr=subprocess.PIPE, check=True)
  File "/usr/lib/python3.6/subprocess.py", line 418, in run
    output=stdout, stderr=stderr)
subprocess.CalledProcessError: Command '['/tmp/lookout-sdk-ml/lookout-sdk-v0.7.0', 'review', 'ipv4://localhost:3030', '--from', '35d6677f2e7cd7489e61799b3258bf348924e3ce', '--to', '54ead17f6b8a240b4ab0d2eeff9d1c66c0a6c206', '--git-dir', '/tmp/top-repos-quality-repos-jcz6yxa7/netflix.git', '--log-format', 'json', '--log-level', 'warning', '--config-json', '{"style.format.analyzer.FormatAnalyzer": {"aggregate": true}}']' returned non-zero exit status 1.
--------------------
Failed to process https://github.com/codeceptjs/codeceptjs.git repo
Traceback (most recent call last):
  File "/style-analyzer/lookout/style/format/benchmarks/quality_report.py", line 312, in generate_quality_report
    vnodes_expected_number=vnodes_expected_number)
  File "/style-analyzer/lookout/style/format/benchmarks/quality_report.py", line 137, in measure_quality
    bblfsh=bblfsh, config_json=config)
  File "/lookout-sdk-ml/lookout/core/helpers/analyzer_context_manager.py", line 87, in review
    log_level=log_level, config_json=config_json)
  File "/lookout-sdk-ml/lookout/core/helpers/server.py", line 101, in review
    return self._run("review", fr, to, port, git_dir, bblfsh, log_level, config_json)
  File "/lookout-sdk-ml/lookout/core/helpers/server.py", line 131, in _run
    return subprocess.run(command, stdout=subprocess.PIPE, stderr=subprocess.PIPE, check=True)
  File "/usr/lib/python3.6/subprocess.py", line 418, in run
    output=stdout, stderr=stderr)
subprocess.CalledProcessError: Command '['/tmp/lookout-sdk-ml/lookout-sdk-v0.7.0', 'review', 'ipv4://localhost:3030', '--from', '5164f0090748d2eca00c152d82a55338ac1e21ec', '--to', '42717c09173fdf8276166c7918b0bbd5c9f1055a', '--git-dir', '/tmp/top-repos-quality-repos-al102j9v/codeceptjs.git', '--log-format', 'json', '--log-level', 'warning', '--config-json', '{"style.format.analyzer.FormatAnalyzer": {"aggregate": true}}']' returned non-zero exit status 1.
--------------------
Failed to process https://github.com/lanistor/react-keeper.git repo
Traceback (most recent call last):
  File "/style-analyzer/lookout/style/format/benchmarks/quality_report.py", line 312, in generate_quality_report
    vnodes_expected_number=vnodes_expected_number)
  File "/style-analyzer/lookout/style/format/benchmarks/quality_report.py", line 137, in measure_quality
    bblfsh=bblfsh, config_json=config)
  File "/lookout-sdk-ml/lookout/core/helpers/analyzer_context_manager.py", line 87, in review
    log_level=log_level, config_json=config_json)
  File "/lookout-sdk-ml/lookout/core/helpers/server.py", line 101, in review
    return self._run("review", fr, to, port, git_dir, bblfsh, log_level, config_json)
  File "/lookout-sdk-ml/lookout/core/helpers/server.py", line 131, in _run
    return subprocess.run(command, stdout=subprocess.PIPE, stderr=subprocess.PIPE, check=True)
  File "/usr/lib/python3.6/subprocess.py", line 418, in run
    output=stdout, stderr=stderr)
subprocess.CalledProcessError: Command '['/tmp/lookout-sdk-ml/lookout-sdk-v0.7.0', 'review', 'ipv4://localhost:3030', '--from', '3fd1eeecdcd7a97077f50dffaf8674e72819daac', '--to', 'e2d9a62e06d79744b48f11875be862921aec0819', '--git-dir', '/tmp/top-repos-quality-repos-t5oeqn3_/react-keeper.git', '--log-format', 'json', '--log-level', 'warning', '--config-json', '{"style.format.analyzer.FormatAnalyzer": {"aggregate": true}}']' returned non-zero exit status 1.
--------------------
Failed to process https://github.com/atom/markdown-preview.git repo
Traceback (most recent call last):
  File "/style-analyzer/lookout/style/format/benchmarks/quality_report.py", line 312, in generate_quality_report
    vnodes_expected_number=vnodes_expected_number)
  File "/style-analyzer/lookout/style/format/benchmarks/quality_report.py", line 137, in measure_quality
    bblfsh=bblfsh, config_json=config)
  File "/lookout-sdk-ml/lookout/core/helpers/analyzer_context_manager.py", line 87, in review
    log_level=log_level, config_json=config_json)
  File "/lookout-sdk-ml/lookout/core/helpers/server.py", line 101, in review
    return self._run("review", fr, to, port, git_dir, bblfsh, log_level, config_json)
  File "/lookout-sdk-ml/lookout/core/helpers/server.py", line 131, in _run
    return subprocess.run(command, stdout=subprocess.PIPE, stderr=subprocess.PIPE, check=True)
  File "/usr/lib/python3.6/subprocess.py", line 418, in run
    output=stdout, stderr=stderr)
subprocess.CalledProcessError: Command '['/tmp/lookout-sdk-ml/lookout-sdk-v0.7.0', 'review', 'ipv4://localhost:3030', '--from', '9c0a9f54f274c990c06bb40c37c7dd2a36f524b2', '--to', '236bdb9d3232a9819ba5d0407f354264ad3223fa', '--git-dir', '/tmp/top-repos-quality-repos-7segqgqs/markdown-preview.git', '--log-format', 'json', '--log-level', 'warning', '--config-json', '{"style.format.analyzer.FormatAnalyzer": {"aggregate": true}}']' returned non-zero exit status 1.
