--------------------
Failed to process https://github.com/felkamp/moviesforme.git repo
Traceback (most recent call last):
  File "/style-analyzer/lookout/style/format/benchmarks/quality_report.py", line 312, in generate_quality_report
    vnodes_expected_number=vnodes_expected_number)
  File "/style-analyzer/lookout/style/format/benchmarks/quality_report.py", line 123, in measure_quality
    git_dir = ensure_repo(repository, tmpdirname)
  File "/style-analyzer/lookout/style/format/benchmarks/quality_report.py", line 54, in ensure_repo
    porcelain.clone(repository, git_dir)
  File "/usr/local/lib/python3.6/dist-packages/dulwich/porcelain.py", line 353, in clone
    depth=depth, **kwargs)
  File "/usr/local/lib/python3.6/dist-packages/dulwich/porcelain.py", line 1121, in fetch
    depth=depth)
  File "/usr/local/lib/python3.6/dist-packages/dulwich/client.py", line 398, in fetch
    progress=progress, depth=depth)
  File "/usr/local/lib/python3.6/dist-packages/dulwich/client.py", line 1644, in fetch_pack
    b"git-upload-pack", url)
  File "/usr/local/lib/python3.6/dist-packages/dulwich/client.py", line 1532, in _discover_references
    resp, read = self._http_request(url, headers, allow_compression=True)
  File "/usr/local/lib/python3.6/dist-packages/dulwich/client.py", line 1510, in _http_request
    (resp.status, url))
dulwich.errors.GitProtocolError: unexpected http resp 401 for https://github.com/felkamp/moviesforme.git/info/refs?service=git-upload-pack
--------------------
Failed to process https://github.com/matsobanemokomane/datascientist.git repo
Traceback (most recent call last):
  File "/style-analyzer/lookout/style/format/benchmarks/quality_report.py", line 312, in generate_quality_report
    vnodes_expected_number=vnodes_expected_number)
  File "/style-analyzer/lookout/style/format/benchmarks/quality_report.py", line 137, in measure_quality
    bblfsh=bblfsh, config_json=config)
  File "/lookout-sdk-ml/lookout/core/helpers/analyzer_context_manager.py", line 87, in review
    log_level=log_level, config_json=config_json)
  File "/lookout-sdk-ml/lookout/core/helpers/server.py", line 101, in review
    return self._run("review", fr, to, port, git_dir, bblfsh, log_level, config_json)
  File "/lookout-sdk-ml/lookout/core/helpers/server.py", line 131, in _run
    return subprocess.run(command, stdout=subprocess.PIPE, stderr=subprocess.PIPE, check=True)
  File "/usr/lib/python3.6/subprocess.py", line 418, in run
    output=stdout, stderr=stderr)
subprocess.CalledProcessError: Command '['/tmp/lookout-sdk-ml/lookout-sdk-v0.7.0', 'review', 'ipv4://localhost:9134', '--from', '53142edfa6f5dcbb34b49d7c9337dea9a97c4cca', '--to', '595b779e19d7ed66267b248e9812935a82aa2261', '--git-dir', '/tmp/top-repos-quality-repos-e_wf7e5l/datascientist.git', '--log-format', 'json', '--log-level', 'warning', '--config-json', '{"style.format.analyzer.FormatAnalyzer": {"aggregate": true}}']' returned non-zero exit status 1.
--------------------
Failed to process https://github.com/rust-lang/rustc-pr-tracking.git repo
Traceback (most recent call last):
  File "/style-analyzer/lookout/style/format/benchmarks/quality_report.py", line 312, in generate_quality_report
    vnodes_expected_number=vnodes_expected_number)
  File "/style-analyzer/lookout/style/format/benchmarks/quality_report.py", line 137, in measure_quality
    bblfsh=bblfsh, config_json=config)
  File "/lookout-sdk-ml/lookout/core/helpers/analyzer_context_manager.py", line 87, in review
    log_level=log_level, config_json=config_json)
  File "/lookout-sdk-ml/lookout/core/helpers/server.py", line 101, in review
    return self._run("review", fr, to, port, git_dir, bblfsh, log_level, config_json)
  File "/lookout-sdk-ml/lookout/core/helpers/server.py", line 131, in _run
    return subprocess.run(command, stdout=subprocess.PIPE, stderr=subprocess.PIPE, check=True)
  File "/usr/lib/python3.6/subprocess.py", line 418, in run
    output=stdout, stderr=stderr)
subprocess.CalledProcessError: Command '['/tmp/lookout-sdk-ml/lookout-sdk-v0.7.0', 'review', 'ipv4://localhost:9134', '--from', 'd9f6ffd1f94dae5f55107af38cfe76549d466e84', '--to', 'b3e49268e5d34de89a0ba74bf86b7ab537955438', '--git-dir', '/tmp/top-repos-quality-repos-qhz1vkl0/rustc-pr-tracking.git', '--log-format', 'json', '--log-level', 'warning', '--config-json', '{"style.format.analyzer.FormatAnalyzer": {"aggregate": true}}']' returned non-zero exit status 1.
