--------------------
Failed to process https://github.com/joeflack4/just-a-dash.git repo
Traceback (most recent call last):
  File "/style-analyzer/lookout/style/format/benchmarks/quality_report.py", line 312, in generate_quality_report
    vnodes_expected_number=vnodes_expected_number)
  File "/style-analyzer/lookout/style/format/benchmarks/quality_report.py", line 135, in measure_quality
    (restarts, repository))
RuntimeError: Run out of 3 attempts. Failed to train proper model for https://github.com/joeflack4/just-a-dash.git.
--------------------
Failed to process https://github.com/dalimil/eventbrite-tools.git repo
Traceback (most recent call last):
  File "/style-analyzer/lookout/style/format/benchmarks/quality_report.py", line 312, in generate_quality_report
    vnodes_expected_number=vnodes_expected_number)
  File "/style-analyzer/lookout/style/format/benchmarks/quality_report.py", line 135, in measure_quality
    (restarts, repository))
RuntimeError: Run out of 3 attempts. Failed to train proper model for https://github.com/dalimil/eventbrite-tools.git.
--------------------
Failed to process https://github.com/modelobootcamp/15-interactive-visualizations-and-dashboards.git repo
Traceback (most recent call last):
  File "/style-analyzer/lookout/style/format/benchmarks/quality_report.py", line 312, in generate_quality_report
    vnodes_expected_number=vnodes_expected_number)
  File "/style-analyzer/lookout/style/format/benchmarks/quality_report.py", line 135, in measure_quality
    (restarts, repository))
RuntimeError: Run out of 3 attempts. Failed to train proper model for https://github.com/modelobootcamp/15-interactive-visualizations-and-dashboards.git.
--------------------
Failed to process https://github.com/deissh/disgraceful.git repo
Traceback (most recent call last):
  File "/style-analyzer/lookout/style/format/benchmarks/quality_report.py", line 312, in generate_quality_report
    vnodes_expected_number=vnodes_expected_number)
  File "/style-analyzer/lookout/style/format/benchmarks/quality_report.py", line 135, in measure_quality
    (restarts, repository))
RuntimeError: Run out of 3 attempts. Failed to train proper model for https://github.com/deissh/disgraceful.git.
