--------------------
Failed to process https://github.com/cornul11/retaily.git repo
Traceback (most recent call last):
  File "/style-analyzer/lookout/style/format/benchmarks/quality_report.py", line 312, in generate_quality_report
    vnodes_expected_number=vnodes_expected_number)
  File "/style-analyzer/lookout/style/format/benchmarks/quality_report.py", line 137, in measure_quality
    bblfsh=bblfsh, config_json=config)
  File "/lookout-sdk-ml/lookout/core/helpers/analyzer_context_manager.py", line 87, in review
    log_level=log_level, config_json=config_json)
  File "/lookout-sdk-ml/lookout/core/helpers/server.py", line 101, in review
    return self._run("review", fr, to, port, git_dir, bblfsh, log_level, config_json)
  File "/lookout-sdk-ml/lookout/core/helpers/server.py", line 131, in _run
    return subprocess.run(command, stdout=subprocess.PIPE, stderr=subprocess.PIPE, check=True)
  File "/usr/lib/python3.6/subprocess.py", line 418, in run
    output=stdout, stderr=stderr)
subprocess.CalledProcessError: Command '['/tmp/lookout-sdk-ml/lookout-sdk-v0.7.0', 'review', 'ipv4://localhost:1392', '--from', '39acce4905146fedcb32494e2babd32eefb09d3b', '--to', 'e8107f7464240581043d96ea650c45cd3470f708', '--git-dir', '/tmp/top-repos-quality-repos-rolcbj6g/retaily.git', '--log-format', 'json', '--log-level', 'warning', '--config-json', '{"style.format.analyzer.FormatAnalyzer": {"aggregate": true}}']' returned non-zero exit status 1.
--------------------
Failed to process https://github.com/qeireal/qa_bot.git repo
Traceback (most recent call last):
  File "/style-analyzer/lookout/style/format/benchmarks/quality_report.py", line 312, in generate_quality_report
    vnodes_expected_number=vnodes_expected_number)
  File "/style-analyzer/lookout/style/format/benchmarks/quality_report.py", line 137, in measure_quality
    bblfsh=bblfsh, config_json=config)
  File "/lookout-sdk-ml/lookout/core/helpers/analyzer_context_manager.py", line 87, in review
    log_level=log_level, config_json=config_json)
  File "/lookout-sdk-ml/lookout/core/helpers/server.py", line 101, in review
    return self._run("review", fr, to, port, git_dir, bblfsh, log_level, config_json)
  File "/lookout-sdk-ml/lookout/core/helpers/server.py", line 131, in _run
    return subprocess.run(command, stdout=subprocess.PIPE, stderr=subprocess.PIPE, check=True)
  File "/usr/lib/python3.6/subprocess.py", line 418, in run
    output=stdout, stderr=stderr)
subprocess.CalledProcessError: Command '['/tmp/lookout-sdk-ml/lookout-sdk-v0.7.0', 'review', 'ipv4://localhost:1392', '--from', 'cd128c23269e165cd9b5cd72de576d274612472d', '--to', '54fb76199c1a0fd4449fe85c005f80634555eb2d', '--git-dir', '/tmp/top-repos-quality-repos-n9jc0wii/qa_bot.git', '--log-format', 'json', '--log-level', 'warning', '--config-json', '{"style.format.analyzer.FormatAnalyzer": {"aggregate": true}}']' returned non-zero exit status 1.
--------------------
Failed to process https://github.com/bnznamco/djsuperadmin.git repo
Traceback (most recent call last):
  File "/style-analyzer/lookout/style/format/benchmarks/quality_report.py", line 312, in generate_quality_report
    vnodes_expected_number=vnodes_expected_number)
  File "/style-analyzer/lookout/style/format/benchmarks/quality_report.py", line 135, in measure_quality
    (restarts, repository))
RuntimeError: Run out of 3 attempts. Failed to train proper model for https://github.com/bnznamco/djsuperadmin.git.
--------------------
Failed to process https://github.com/the-marcy-lab-school/problem-set-x-stacks-queues.git repo
Traceback (most recent call last):
  File "/style-analyzer/lookout/style/format/benchmarks/quality_report.py", line 312, in generate_quality_report
    vnodes_expected_number=vnodes_expected_number)
  File "/style-analyzer/lookout/style/format/benchmarks/quality_report.py", line 135, in measure_quality
    (restarts, repository))
RuntimeError: Run out of 3 attempts. Failed to train proper model for https://github.com/the-marcy-lab-school/problem-set-x-stacks-queues.git.
--------------------
Failed to process https://github.com/sorrykim/weathertoto.git repo
Traceback (most recent call last):
  File "/style-analyzer/lookout/style/format/benchmarks/quality_report.py", line 312, in generate_quality_report
    vnodes_expected_number=vnodes_expected_number)
  File "/style-analyzer/lookout/style/format/benchmarks/quality_report.py", line 137, in measure_quality
    bblfsh=bblfsh, config_json=config)
  File "/lookout-sdk-ml/lookout/core/helpers/analyzer_context_manager.py", line 87, in review
    log_level=log_level, config_json=config_json)
  File "/lookout-sdk-ml/lookout/core/helpers/server.py", line 101, in review
    return self._run("review", fr, to, port, git_dir, bblfsh, log_level, config_json)
  File "/lookout-sdk-ml/lookout/core/helpers/server.py", line 131, in _run
    return subprocess.run(command, stdout=subprocess.PIPE, stderr=subprocess.PIPE, check=True)
  File "/usr/lib/python3.6/subprocess.py", line 418, in run
    output=stdout, stderr=stderr)
subprocess.CalledProcessError: Command '['/tmp/lookout-sdk-ml/lookout-sdk-v0.7.0', 'review', 'ipv4://localhost:1392', '--from', 'fb7658d4c494cb933d80695e6cd5745b68413981', '--to', '7b281c33df0dd8f8c6911b3c971aba6211f31c20', '--git-dir', '/tmp/top-repos-quality-repos-tgrytwde/weathertoto.git', '--log-format', 'json', '--log-level', 'warning', '--config-json', '{"style.format.analyzer.FormatAnalyzer": {"aggregate": true}}']' returned non-zero exit status 1.
--------------------
Failed to process https://github.com/qu3vipon/tdd-practice.git repo
Traceback (most recent call last):
  File "/style-analyzer/lookout/style/format/benchmarks/quality_report.py", line 312, in generate_quality_report
    vnodes_expected_number=vnodes_expected_number)
  File "/style-analyzer/lookout/style/format/benchmarks/quality_report.py", line 137, in measure_quality
    bblfsh=bblfsh, config_json=config)
  File "/lookout-sdk-ml/lookout/core/helpers/analyzer_context_manager.py", line 87, in review
    log_level=log_level, config_json=config_json)
  File "/lookout-sdk-ml/lookout/core/helpers/server.py", line 101, in review
    return self._run("review", fr, to, port, git_dir, bblfsh, log_level, config_json)
  File "/lookout-sdk-ml/lookout/core/helpers/server.py", line 131, in _run
    return subprocess.run(command, stdout=subprocess.PIPE, stderr=subprocess.PIPE, check=True)
  File "/usr/lib/python3.6/subprocess.py", line 418, in run
    output=stdout, stderr=stderr)
subprocess.CalledProcessError: Command '['/tmp/lookout-sdk-ml/lookout-sdk-v0.7.0', 'review', 'ipv4://localhost:1392', '--from', '60bc10e6aa211387ebbd0f85e62b9cc1f056f2f1', '--to', '73f022458cf3e498fbb41358aeb1701c5193d28f', '--git-dir', '/tmp/top-repos-quality-repos-4vbev37j/tdd-practice.git', '--log-format', 'json', '--log-level', 'warning', '--config-json', '{"style.format.analyzer.FormatAnalyzer": {"aggregate": true}}']' returned non-zero exit status 1.
--------------------
Failed to process https://github.com/holland01/yaq3r.git repo
Traceback (most recent call last):
  File "/style-analyzer/lookout/style/format/benchmarks/quality_report.py", line 312, in generate_quality_report
    vnodes_expected_number=vnodes_expected_number)
  File "/style-analyzer/lookout/style/format/benchmarks/quality_report.py", line 137, in measure_quality
    bblfsh=bblfsh, config_json=config)
  File "/lookout-sdk-ml/lookout/core/helpers/analyzer_context_manager.py", line 87, in review
    log_level=log_level, config_json=config_json)
  File "/lookout-sdk-ml/lookout/core/helpers/server.py", line 101, in review
    return self._run("review", fr, to, port, git_dir, bblfsh, log_level, config_json)
  File "/lookout-sdk-ml/lookout/core/helpers/server.py", line 131, in _run
    return subprocess.run(command, stdout=subprocess.PIPE, stderr=subprocess.PIPE, check=True)
  File "/usr/lib/python3.6/subprocess.py", line 418, in run
    output=stdout, stderr=stderr)
subprocess.CalledProcessError: Command '['/tmp/lookout-sdk-ml/lookout-sdk-v0.7.0', 'review', 'ipv4://localhost:1392', '--from', 'f974be37b7ff72c67f03ebc34374de53373326c9', '--to', 'c77031616d99b2a63e371aa1e31da576ab37c975', '--git-dir', '/tmp/top-repos-quality-repos-iqgtown_/yaq3r.git', '--log-format', 'json', '--log-level', 'warning', '--config-json', '{"style.format.analyzer.FormatAnalyzer": {"aggregate": true}}']' returned non-zero exit status 1.
--------------------
Failed to process https://github.com/hcote/sandbox.git repo
Traceback (most recent call last):
  File "/style-analyzer/lookout/style/format/benchmarks/quality_report.py", line 312, in generate_quality_report
    vnodes_expected_number=vnodes_expected_number)
  File "/style-analyzer/lookout/style/format/benchmarks/quality_report.py", line 135, in measure_quality
    (restarts, repository))
RuntimeError: Run out of 3 attempts. Failed to train proper model for https://github.com/hcote/sandbox.git.
--------------------
Failed to process https://github.com/shinelikastar/coloringbooks.git repo
Traceback (most recent call last):
  File "/style-analyzer/lookout/style/format/benchmarks/quality_report.py", line 312, in generate_quality_report
    vnodes_expected_number=vnodes_expected_number)
  File "/style-analyzer/lookout/style/format/benchmarks/quality_report.py", line 137, in measure_quality
    bblfsh=bblfsh, config_json=config)
  File "/lookout-sdk-ml/lookout/core/helpers/analyzer_context_manager.py", line 87, in review
    log_level=log_level, config_json=config_json)
  File "/lookout-sdk-ml/lookout/core/helpers/server.py", line 101, in review
    return self._run("review", fr, to, port, git_dir, bblfsh, log_level, config_json)
  File "/lookout-sdk-ml/lookout/core/helpers/server.py", line 131, in _run
    return subprocess.run(command, stdout=subprocess.PIPE, stderr=subprocess.PIPE, check=True)
  File "/usr/lib/python3.6/subprocess.py", line 418, in run
    output=stdout, stderr=stderr)
subprocess.CalledProcessError: Command '['/tmp/lookout-sdk-ml/lookout-sdk-v0.7.0', 'review', 'ipv4://localhost:1392', '--from', '5414bcafcfa6095566c5347596bee5170bfc1456', '--to', '34258e51595c43de0583ba024b3c2bee00cf0965', '--git-dir', '/tmp/top-repos-quality-repos-59l_l666/coloringbooks.git', '--log-format', 'json', '--log-level', 'warning', '--config-json', '{"style.format.analyzer.FormatAnalyzer": {"aggregate": true}}']' returned non-zero exit status 1.
--------------------
Failed to process https://github.com/geoffreynguyen011/eseaplayoffsinfo.git repo
Traceback (most recent call last):
  File "/style-analyzer/lookout/style/format/benchmarks/quality_report.py", line 312, in generate_quality_report
    vnodes_expected_number=vnodes_expected_number)
  File "/style-analyzer/lookout/style/format/benchmarks/quality_report.py", line 135, in measure_quality
    (restarts, repository))
RuntimeError: Run out of 3 attempts. Failed to train proper model for https://github.com/geoffreynguyen011/eseaplayoffsinfo.git.
--------------------
Failed to process https://github.com/ormaza/data-structure.git repo
Traceback (most recent call last):
  File "/style-analyzer/lookout/style/format/benchmarks/quality_report.py", line 312, in generate_quality_report
    vnodes_expected_number=vnodes_expected_number)
  File "/style-analyzer/lookout/style/format/benchmarks/quality_report.py", line 137, in measure_quality
    bblfsh=bblfsh, config_json=config)
  File "/lookout-sdk-ml/lookout/core/helpers/analyzer_context_manager.py", line 87, in review
    log_level=log_level, config_json=config_json)
  File "/lookout-sdk-ml/lookout/core/helpers/server.py", line 101, in review
    return self._run("review", fr, to, port, git_dir, bblfsh, log_level, config_json)
  File "/lookout-sdk-ml/lookout/core/helpers/server.py", line 131, in _run
    return subprocess.run(command, stdout=subprocess.PIPE, stderr=subprocess.PIPE, check=True)
  File "/usr/lib/python3.6/subprocess.py", line 418, in run
    output=stdout, stderr=stderr)
subprocess.CalledProcessError: Command '['/tmp/lookout-sdk-ml/lookout-sdk-v0.7.0', 'review', 'ipv4://localhost:1392', '--from', '5bb7a3fea75b99b78b6512d2eae3e215eba66eb4', '--to', '4f3995d8d0c6dfeb0ea55ef9f68c704d3d583418', '--git-dir', '/tmp/top-repos-quality-repos-7k7pk06q/data-structure.git', '--log-format', 'json', '--log-level', 'warning', '--config-json', '{"style.format.analyzer.FormatAnalyzer": {"aggregate": true}}']' returned non-zero exit status 1.
--------------------
Failed to process https://github.com/cornul11/retaily.git repo
Traceback (most recent call last):
  File "/style-analyzer/lookout/style/format/benchmarks/quality_report.py", line 312, in generate_quality_report
    vnodes_expected_number=vnodes_expected_number)
  File "/style-analyzer/lookout/style/format/benchmarks/quality_report.py", line 137, in measure_quality
    bblfsh=bblfsh, config_json=config)
  File "/lookout-sdk-ml/lookout/core/helpers/analyzer_context_manager.py", line 87, in review
    log_level=log_level, config_json=config_json)
  File "/lookout-sdk-ml/lookout/core/helpers/server.py", line 101, in review
    return self._run("review", fr, to, port, git_dir, bblfsh, log_level, config_json)
  File "/lookout-sdk-ml/lookout/core/helpers/server.py", line 131, in _run
    return subprocess.run(command, stdout=subprocess.PIPE, stderr=subprocess.PIPE, check=True)
  File "/usr/lib/python3.6/subprocess.py", line 418, in run
    output=stdout, stderr=stderr)
subprocess.CalledProcessError: Command '['/tmp/lookout-sdk-ml/lookout-sdk-v0.7.0', 'review', 'ipv4://localhost:9227', '--from', '39acce4905146fedcb32494e2babd32eefb09d3b', '--to', 'e8107f7464240581043d96ea650c45cd3470f708', '--git-dir', '/tmp/top-repos-quality-repos-j7eoh1c3/retaily.git', '--log-format', 'json', '--log-level', 'warning', '--config-json', '{"style.format.analyzer.FormatAnalyzer": {"aggregate": true}}']' returned non-zero exit status 1.
--------------------
Failed to process https://github.com/qeireal/qa_bot.git repo
Traceback (most recent call last):
  File "/style-analyzer/lookout/style/format/benchmarks/quality_report.py", line 312, in generate_quality_report
    vnodes_expected_number=vnodes_expected_number)
  File "/style-analyzer/lookout/style/format/benchmarks/quality_report.py", line 137, in measure_quality
    bblfsh=bblfsh, config_json=config)
  File "/lookout-sdk-ml/lookout/core/helpers/analyzer_context_manager.py", line 87, in review
    log_level=log_level, config_json=config_json)
  File "/lookout-sdk-ml/lookout/core/helpers/server.py", line 101, in review
    return self._run("review", fr, to, port, git_dir, bblfsh, log_level, config_json)
  File "/lookout-sdk-ml/lookout/core/helpers/server.py", line 131, in _run
    return subprocess.run(command, stdout=subprocess.PIPE, stderr=subprocess.PIPE, check=True)
  File "/usr/lib/python3.6/subprocess.py", line 418, in run
    output=stdout, stderr=stderr)
subprocess.CalledProcessError: Command '['/tmp/lookout-sdk-ml/lookout-sdk-v0.7.0', 'review', 'ipv4://localhost:9227', '--from', 'cd128c23269e165cd9b5cd72de576d274612472d', '--to', '54fb76199c1a0fd4449fe85c005f80634555eb2d', '--git-dir', '/tmp/top-repos-quality-repos-616mdnwm/qa_bot.git', '--log-format', 'json', '--log-level', 'warning', '--config-json', '{"style.format.analyzer.FormatAnalyzer": {"aggregate": true}}']' returned non-zero exit status 1.
--------------------
Failed to process https://github.com/bnznamco/djsuperadmin.git repo
Traceback (most recent call last):
  File "/style-analyzer/lookout/style/format/benchmarks/quality_report.py", line 312, in generate_quality_report
    vnodes_expected_number=vnodes_expected_number)
  File "/style-analyzer/lookout/style/format/benchmarks/quality_report.py", line 135, in measure_quality
    (restarts, repository))
RuntimeError: Run out of 3 attempts. Failed to train proper model for https://github.com/bnznamco/djsuperadmin.git.
--------------------
Failed to process https://github.com/the-marcy-lab-school/problem-set-x-stacks-queues.git repo
Traceback (most recent call last):
  File "/style-analyzer/lookout/style/format/benchmarks/quality_report.py", line 312, in generate_quality_report
    vnodes_expected_number=vnodes_expected_number)
  File "/style-analyzer/lookout/style/format/benchmarks/quality_report.py", line 135, in measure_quality
    (restarts, repository))
RuntimeError: Run out of 3 attempts. Failed to train proper model for https://github.com/the-marcy-lab-school/problem-set-x-stacks-queues.git.
--------------------
Failed to process https://github.com/sorrykim/weathertoto.git repo
Traceback (most recent call last):
  File "/style-analyzer/lookout/style/format/benchmarks/quality_report.py", line 312, in generate_quality_report
    vnodes_expected_number=vnodes_expected_number)
  File "/style-analyzer/lookout/style/format/benchmarks/quality_report.py", line 137, in measure_quality
    bblfsh=bblfsh, config_json=config)
  File "/lookout-sdk-ml/lookout/core/helpers/analyzer_context_manager.py", line 87, in review
    log_level=log_level, config_json=config_json)
  File "/lookout-sdk-ml/lookout/core/helpers/server.py", line 101, in review
    return self._run("review", fr, to, port, git_dir, bblfsh, log_level, config_json)
  File "/lookout-sdk-ml/lookout/core/helpers/server.py", line 131, in _run
    return subprocess.run(command, stdout=subprocess.PIPE, stderr=subprocess.PIPE, check=True)
  File "/usr/lib/python3.6/subprocess.py", line 418, in run
    output=stdout, stderr=stderr)
subprocess.CalledProcessError: Command '['/tmp/lookout-sdk-ml/lookout-sdk-v0.7.0', 'review', 'ipv4://localhost:9227', '--from', 'fb7658d4c494cb933d80695e6cd5745b68413981', '--to', '7b281c33df0dd8f8c6911b3c971aba6211f31c20', '--git-dir', '/tmp/top-repos-quality-repos-qiglhpu1/weathertoto.git', '--log-format', 'json', '--log-level', 'warning', '--config-json', '{"style.format.analyzer.FormatAnalyzer": {"aggregate": true}}']' returned non-zero exit status 1.
--------------------
Failed to process https://github.com/qu3vipon/tdd-practice.git repo
Traceback (most recent call last):
  File "/style-analyzer/lookout/style/format/benchmarks/quality_report.py", line 312, in generate_quality_report
    vnodes_expected_number=vnodes_expected_number)
  File "/style-analyzer/lookout/style/format/benchmarks/quality_report.py", line 137, in measure_quality
    bblfsh=bblfsh, config_json=config)
  File "/lookout-sdk-ml/lookout/core/helpers/analyzer_context_manager.py", line 87, in review
    log_level=log_level, config_json=config_json)
  File "/lookout-sdk-ml/lookout/core/helpers/server.py", line 101, in review
    return self._run("review", fr, to, port, git_dir, bblfsh, log_level, config_json)
  File "/lookout-sdk-ml/lookout/core/helpers/server.py", line 131, in _run
    return subprocess.run(command, stdout=subprocess.PIPE, stderr=subprocess.PIPE, check=True)
  File "/usr/lib/python3.6/subprocess.py", line 418, in run
    output=stdout, stderr=stderr)
subprocess.CalledProcessError: Command '['/tmp/lookout-sdk-ml/lookout-sdk-v0.7.0', 'review', 'ipv4://localhost:9227', '--from', '60bc10e6aa211387ebbd0f85e62b9cc1f056f2f1', '--to', '73f022458cf3e498fbb41358aeb1701c5193d28f', '--git-dir', '/tmp/top-repos-quality-repos-kynsuie8/tdd-practice.git', '--log-format', 'json', '--log-level', 'warning', '--config-json', '{"style.format.analyzer.FormatAnalyzer": {"aggregate": true}}']' returned non-zero exit status 1.
--------------------
Failed to process https://github.com/cornul11/retaily.git repo
Traceback (most recent call last):
  File "/style-analyzer/lookout/style/format/benchmarks/quality_report.py", line 312, in generate_quality_report
    vnodes_expected_number=vnodes_expected_number)
  File "/style-analyzer/lookout/style/format/benchmarks/quality_report.py", line 137, in measure_quality
    bblfsh=bblfsh, config_json=config)
  File "/lookout-sdk-ml/lookout/core/helpers/analyzer_context_manager.py", line 87, in review
    log_level=log_level, config_json=config_json)
  File "/lookout-sdk-ml/lookout/core/helpers/server.py", line 101, in review
    return self._run("review", fr, to, port, git_dir, bblfsh, log_level, config_json)
  File "/lookout-sdk-ml/lookout/core/helpers/server.py", line 131, in _run
    return subprocess.run(command, stdout=subprocess.PIPE, stderr=subprocess.PIPE, check=True)
  File "/usr/lib/python3.6/subprocess.py", line 418, in run
    output=stdout, stderr=stderr)
subprocess.CalledProcessError: Command '['/tmp/lookout-sdk-ml/lookout-sdk-v0.7.0', 'review', 'ipv4://localhost:3271', '--from', '39acce4905146fedcb32494e2babd32eefb09d3b', '--to', 'e8107f7464240581043d96ea650c45cd3470f708', '--git-dir', '/tmp/top-repos-quality-repos-x2ck19rb/retaily.git', '--log-format', 'json', '--log-level', 'warning', '--config-json', '{"style.format.analyzer.FormatAnalyzer": {"aggregate": true}}']' returned non-zero exit status 1.
--------------------
Failed to process https://github.com/qeireal/qa_bot.git repo
Traceback (most recent call last):
  File "/style-analyzer/lookout/style/format/benchmarks/quality_report.py", line 312, in generate_quality_report
    vnodes_expected_number=vnodes_expected_number)
  File "/style-analyzer/lookout/style/format/benchmarks/quality_report.py", line 137, in measure_quality
    bblfsh=bblfsh, config_json=config)
  File "/lookout-sdk-ml/lookout/core/helpers/analyzer_context_manager.py", line 87, in review
    log_level=log_level, config_json=config_json)
  File "/lookout-sdk-ml/lookout/core/helpers/server.py", line 101, in review
    return self._run("review", fr, to, port, git_dir, bblfsh, log_level, config_json)
  File "/lookout-sdk-ml/lookout/core/helpers/server.py", line 131, in _run
    return subprocess.run(command, stdout=subprocess.PIPE, stderr=subprocess.PIPE, check=True)
  File "/usr/lib/python3.6/subprocess.py", line 418, in run
    output=stdout, stderr=stderr)
subprocess.CalledProcessError: Command '['/tmp/lookout-sdk-ml/lookout-sdk-v0.7.0', 'review', 'ipv4://localhost:3271', '--from', 'cd128c23269e165cd9b5cd72de576d274612472d', '--to', '54fb76199c1a0fd4449fe85c005f80634555eb2d', '--git-dir', '/tmp/top-repos-quality-repos-021tcgyx/qa_bot.git', '--log-format', 'json', '--log-level', 'warning', '--config-json', '{"style.format.analyzer.FormatAnalyzer": {"aggregate": true}}']' returned non-zero exit status 1.
--------------------
Failed to process https://github.com/bnznamco/djsuperadmin.git repo
Traceback (most recent call last):
  File "/style-analyzer/lookout/style/format/benchmarks/quality_report.py", line 312, in generate_quality_report
    vnodes_expected_number=vnodes_expected_number)
  File "/style-analyzer/lookout/style/format/benchmarks/quality_report.py", line 135, in measure_quality
    (restarts, repository))
RuntimeError: Run out of 3 attempts. Failed to train proper model for https://github.com/bnznamco/djsuperadmin.git.
--------------------
Failed to process https://github.com/the-marcy-lab-school/problem-set-x-stacks-queues.git repo
Traceback (most recent call last):
  File "/style-analyzer/lookout/style/format/benchmarks/quality_report.py", line 312, in generate_quality_report
    vnodes_expected_number=vnodes_expected_number)
  File "/style-analyzer/lookout/style/format/benchmarks/quality_report.py", line 135, in measure_quality
    (restarts, repository))
RuntimeError: Run out of 3 attempts. Failed to train proper model for https://github.com/the-marcy-lab-school/problem-set-x-stacks-queues.git.
--------------------
Failed to process https://github.com/sorrykim/weathertoto.git repo
Traceback (most recent call last):
  File "/style-analyzer/lookout/style/format/benchmarks/quality_report.py", line 312, in generate_quality_report
    vnodes_expected_number=vnodes_expected_number)
  File "/style-analyzer/lookout/style/format/benchmarks/quality_report.py", line 137, in measure_quality
    bblfsh=bblfsh, config_json=config)
  File "/lookout-sdk-ml/lookout/core/helpers/analyzer_context_manager.py", line 87, in review
    log_level=log_level, config_json=config_json)
  File "/lookout-sdk-ml/lookout/core/helpers/server.py", line 101, in review
    return self._run("review", fr, to, port, git_dir, bblfsh, log_level, config_json)
  File "/lookout-sdk-ml/lookout/core/helpers/server.py", line 131, in _run
    return subprocess.run(command, stdout=subprocess.PIPE, stderr=subprocess.PIPE, check=True)
  File "/usr/lib/python3.6/subprocess.py", line 418, in run
    output=stdout, stderr=stderr)
subprocess.CalledProcessError: Command '['/tmp/lookout-sdk-ml/lookout-sdk-v0.7.0', 'review', 'ipv4://localhost:3271', '--from', 'fb7658d4c494cb933d80695e6cd5745b68413981', '--to', '7b281c33df0dd8f8c6911b3c971aba6211f31c20', '--git-dir', '/tmp/top-repos-quality-repos-crfs41uy/weathertoto.git', '--log-format', 'json', '--log-level', 'warning', '--config-json', '{"style.format.analyzer.FormatAnalyzer": {"aggregate": true}}']' returned non-zero exit status 1.
--------------------
Failed to process https://github.com/qu3vipon/tdd-practice.git repo
Traceback (most recent call last):
  File "/style-analyzer/lookout/style/format/benchmarks/quality_report.py", line 312, in generate_quality_report
    vnodes_expected_number=vnodes_expected_number)
  File "/style-analyzer/lookout/style/format/benchmarks/quality_report.py", line 137, in measure_quality
    bblfsh=bblfsh, config_json=config)
  File "/lookout-sdk-ml/lookout/core/helpers/analyzer_context_manager.py", line 87, in review
    log_level=log_level, config_json=config_json)
  File "/lookout-sdk-ml/lookout/core/helpers/server.py", line 101, in review
    return self._run("review", fr, to, port, git_dir, bblfsh, log_level, config_json)
  File "/lookout-sdk-ml/lookout/core/helpers/server.py", line 131, in _run
    return subprocess.run(command, stdout=subprocess.PIPE, stderr=subprocess.PIPE, check=True)
  File "/usr/lib/python3.6/subprocess.py", line 418, in run
    output=stdout, stderr=stderr)
subprocess.CalledProcessError: Command '['/tmp/lookout-sdk-ml/lookout-sdk-v0.7.0', 'review', 'ipv4://localhost:3271', '--from', '60bc10e6aa211387ebbd0f85e62b9cc1f056f2f1', '--to', '73f022458cf3e498fbb41358aeb1701c5193d28f', '--git-dir', '/tmp/top-repos-quality-repos-46zs1q7t/tdd-practice.git', '--log-format', 'json', '--log-level', 'warning', '--config-json', '{"style.format.analyzer.FormatAnalyzer": {"aggregate": true}}']' returned non-zero exit status 1.
--------------------
Failed to process https://github.com/holland01/yaq3r.git repo
Traceback (most recent call last):
  File "/style-analyzer/lookout/style/format/benchmarks/quality_report.py", line 312, in generate_quality_report
    vnodes_expected_number=vnodes_expected_number)
  File "/style-analyzer/lookout/style/format/benchmarks/quality_report.py", line 137, in measure_quality
    bblfsh=bblfsh, config_json=config)
  File "/lookout-sdk-ml/lookout/core/helpers/analyzer_context_manager.py", line 87, in review
    log_level=log_level, config_json=config_json)
  File "/lookout-sdk-ml/lookout/core/helpers/server.py", line 101, in review
    return self._run("review", fr, to, port, git_dir, bblfsh, log_level, config_json)
  File "/lookout-sdk-ml/lookout/core/helpers/server.py", line 131, in _run
    return subprocess.run(command, stdout=subprocess.PIPE, stderr=subprocess.PIPE, check=True)
  File "/usr/lib/python3.6/subprocess.py", line 418, in run
    output=stdout, stderr=stderr)
subprocess.CalledProcessError: Command '['/tmp/lookout-sdk-ml/lookout-sdk-v0.7.0', 'review', 'ipv4://localhost:3271', '--from', 'f974be37b7ff72c67f03ebc34374de53373326c9', '--to', 'c77031616d99b2a63e371aa1e31da576ab37c975', '--git-dir', '/tmp/top-repos-quality-repos-hpetj7ke/yaq3r.git', '--log-format', 'json', '--log-level', 'warning', '--config-json', '{"style.format.analyzer.FormatAnalyzer": {"aggregate": true}}']' returned non-zero exit status 1.
--------------------
Failed to process https://github.com/hcote/sandbox.git repo
Traceback (most recent call last):
  File "/style-analyzer/lookout/style/format/benchmarks/quality_report.py", line 312, in generate_quality_report
    vnodes_expected_number=vnodes_expected_number)
  File "/style-analyzer/lookout/style/format/benchmarks/quality_report.py", line 135, in measure_quality
    (restarts, repository))
RuntimeError: Run out of 3 attempts. Failed to train proper model for https://github.com/hcote/sandbox.git.
--------------------
Failed to process https://github.com/shinelikastar/coloringbooks.git repo
Traceback (most recent call last):
  File "/style-analyzer/lookout/style/format/benchmarks/quality_report.py", line 312, in generate_quality_report
    vnodes_expected_number=vnodes_expected_number)
  File "/style-analyzer/lookout/style/format/benchmarks/quality_report.py", line 137, in measure_quality
    bblfsh=bblfsh, config_json=config)
  File "/lookout-sdk-ml/lookout/core/helpers/analyzer_context_manager.py", line 87, in review
    log_level=log_level, config_json=config_json)
  File "/lookout-sdk-ml/lookout/core/helpers/server.py", line 101, in review
    return self._run("review", fr, to, port, git_dir, bblfsh, log_level, config_json)
  File "/lookout-sdk-ml/lookout/core/helpers/server.py", line 131, in _run
    return subprocess.run(command, stdout=subprocess.PIPE, stderr=subprocess.PIPE, check=True)
  File "/usr/lib/python3.6/subprocess.py", line 418, in run
    output=stdout, stderr=stderr)
subprocess.CalledProcessError: Command '['/tmp/lookout-sdk-ml/lookout-sdk-v0.7.0', 'review', 'ipv4://localhost:3271', '--from', '5414bcafcfa6095566c5347596bee5170bfc1456', '--to', '34258e51595c43de0583ba024b3c2bee00cf0965', '--git-dir', '/tmp/top-repos-quality-repos-l5m1z7qt/coloringbooks.git', '--log-format', 'json', '--log-level', 'warning', '--config-json', '{"style.format.analyzer.FormatAnalyzer": {"aggregate": true}}']' returned non-zero exit status 1.
--------------------
Failed to process https://github.com/geoffreynguyen011/eseaplayoffsinfo.git repo
Traceback (most recent call last):
  File "/style-analyzer/lookout/style/format/benchmarks/quality_report.py", line 312, in generate_quality_report
    vnodes_expected_number=vnodes_expected_number)
  File "/style-analyzer/lookout/style/format/benchmarks/quality_report.py", line 135, in measure_quality
    (restarts, repository))
RuntimeError: Run out of 3 attempts. Failed to train proper model for https://github.com/geoffreynguyen011/eseaplayoffsinfo.git.
--------------------
Failed to process https://github.com/ormaza/data-structure.git repo
Traceback (most recent call last):
  File "/style-analyzer/lookout/style/format/benchmarks/quality_report.py", line 312, in generate_quality_report
    vnodes_expected_number=vnodes_expected_number)
  File "/style-analyzer/lookout/style/format/benchmarks/quality_report.py", line 137, in measure_quality
    bblfsh=bblfsh, config_json=config)
  File "/lookout-sdk-ml/lookout/core/helpers/analyzer_context_manager.py", line 87, in review
    log_level=log_level, config_json=config_json)
  File "/lookout-sdk-ml/lookout/core/helpers/server.py", line 101, in review
    return self._run("review", fr, to, port, git_dir, bblfsh, log_level, config_json)
  File "/lookout-sdk-ml/lookout/core/helpers/server.py", line 131, in _run
    return subprocess.run(command, stdout=subprocess.PIPE, stderr=subprocess.PIPE, check=True)
  File "/usr/lib/python3.6/subprocess.py", line 418, in run
    output=stdout, stderr=stderr)
subprocess.CalledProcessError: Command '['/tmp/lookout-sdk-ml/lookout-sdk-v0.7.0', 'review', 'ipv4://localhost:3271', '--from', '5bb7a3fea75b99b78b6512d2eae3e215eba66eb4', '--to', '4f3995d8d0c6dfeb0ea55ef9f68c704d3d583418', '--git-dir', '/tmp/top-repos-quality-repos-lnp88mrg/data-structure.git', '--log-format', 'json', '--log-level', 'warning', '--config-json', '{"style.format.analyzer.FormatAnalyzer": {"aggregate": true}}']' returned non-zero exit status 1.
