--------------------
Failed to process https://github.com/firecubez/lwctb.git repo
Traceback (most recent call last):
  File "/style-analyzer/lookout/style/format/benchmarks/quality_report.py", line 312, in generate_quality_report
    vnodes_expected_number=vnodes_expected_number)
  File "/style-analyzer/lookout/style/format/benchmarks/quality_report.py", line 123, in measure_quality
    git_dir = ensure_repo(repository, tmpdirname)
  File "/style-analyzer/lookout/style/format/benchmarks/quality_report.py", line 54, in ensure_repo
    porcelain.clone(repository, git_dir)
  File "/usr/local/lib/python3.6/dist-packages/dulwich/porcelain.py", line 372, in clone
    r.reset_index(head.tree)
  File "/usr/local/lib/python3.6/dist-packages/dulwich/repo.py", line 1166, in reset_index
    validate_path_element=validate_path_element)
  File "/usr/local/lib/python3.6/dist-packages/dulwich/index.py", line 546, in build_index_from_tree
    obj, entry.mode, full_path, honor_filemode=honor_filemode)
  File "/usr/local/lib/python3.6/dist-packages/dulwich/index.py", line 464, in build_file_from_blob
    os.symlink(contents, target_path)
ValueError: symlink: embedded null character in src
--------------------
Failed to process https://github.com/cornul11/retaily.git repo
Traceback (most recent call last):
  File "/style-analyzer/lookout/style/format/benchmarks/quality_report.py", line 312, in generate_quality_report
    vnodes_expected_number=vnodes_expected_number)
  File "/style-analyzer/lookout/style/format/benchmarks/quality_report.py", line 137, in measure_quality
    bblfsh=bblfsh, config_json=config)
  File "/lookout-sdk-ml/lookout/core/helpers/analyzer_context_manager.py", line 87, in review
    log_level=log_level, config_json=config_json)
  File "/lookout-sdk-ml/lookout/core/helpers/server.py", line 101, in review
    return self._run("review", fr, to, port, git_dir, bblfsh, log_level, config_json)
  File "/lookout-sdk-ml/lookout/core/helpers/server.py", line 131, in _run
    return subprocess.run(command, stdout=subprocess.PIPE, stderr=subprocess.PIPE, check=True)
  File "/usr/lib/python3.6/subprocess.py", line 418, in run
    output=stdout, stderr=stderr)
subprocess.CalledProcessError: Command '['/tmp/lookout-sdk-ml/lookout-sdk-v0.7.0', 'review', 'ipv4://localhost:19139', '--from', '39acce4905146fedcb32494e2babd32eefb09d3b', '--to', 'e8107f7464240581043d96ea650c45cd3470f708', '--git-dir', '/tmp/top-repos-quality-repos-bpwyi2by/retaily.git', '--log-format', 'json', '--log-level', 'warning', '--config-json', '{"style.format.analyzer.FormatAnalyzer": {"aggregate": true}}']' returned non-zero exit status 1.
--------------------
Failed to process https://github.com/kashavarya/pupils-monitoring.git repo
Traceback (most recent call last):
  File "/style-analyzer/lookout/style/format/benchmarks/quality_report.py", line 312, in generate_quality_report
    vnodes_expected_number=vnodes_expected_number)
  File "/style-analyzer/lookout/style/format/benchmarks/quality_report.py", line 137, in measure_quality
    bblfsh=bblfsh, config_json=config)
  File "/lookout-sdk-ml/lookout/core/helpers/analyzer_context_manager.py", line 87, in review
    log_level=log_level, config_json=config_json)
  File "/lookout-sdk-ml/lookout/core/helpers/server.py", line 101, in review
    return self._run("review", fr, to, port, git_dir, bblfsh, log_level, config_json)
  File "/lookout-sdk-ml/lookout/core/helpers/server.py", line 131, in _run
    return subprocess.run(command, stdout=subprocess.PIPE, stderr=subprocess.PIPE, check=True)
  File "/usr/lib/python3.6/subprocess.py", line 418, in run
    output=stdout, stderr=stderr)
subprocess.CalledProcessError: Command '['/tmp/lookout-sdk-ml/lookout-sdk-v0.7.0', 'review', 'ipv4://localhost:19139', '--from', '63f055e09567b2ed4fdf96d0c593372da9662245', '--to', '668b79cffe04b54b399851bd9afc4ba0b1e31817', '--git-dir', '/tmp/top-repos-quality-repos-8ebkpegq/pupils-monitoring.git', '--log-format', 'json', '--log-level', 'warning', '--config-json', '{"style.format.analyzer.FormatAnalyzer": {"aggregate": true}}']' returned non-zero exit status 1.
--------------------
Failed to process https://github.com/xingkong130/hsstf.git repo
Traceback (most recent call last):
  File "/style-analyzer/lookout/style/format/benchmarks/quality_report.py", line 312, in generate_quality_report
    vnodes_expected_number=vnodes_expected_number)
  File "/style-analyzer/lookout/style/format/benchmarks/quality_report.py", line 135, in measure_quality
    (restarts, repository))
RuntimeError: Run out of 3 attempts. Failed to train proper model for https://github.com/xingkong130/hsstf.git.
--------------------
Failed to process https://github.com/proprincekush/machinecontrol.git repo
Traceback (most recent call last):
  File "/style-analyzer/lookout/style/format/benchmarks/quality_report.py", line 312, in generate_quality_report
    vnodes_expected_number=vnodes_expected_number)
  File "/style-analyzer/lookout/style/format/benchmarks/quality_report.py", line 135, in measure_quality
    (restarts, repository))
RuntimeError: Run out of 3 attempts. Failed to train proper model for https://github.com/proprincekush/machinecontrol.git.
