--------------------
Failed to process https://github.com/andyfriesen/v1wasm.git repo
Traceback (most recent call last):
  File "/style-analyzer/lookout/style/format/benchmarks/quality_report.py", line 312, in generate_quality_report
    vnodes_expected_number=vnodes_expected_number)
  File "/style-analyzer/lookout/style/format/benchmarks/quality_report.py", line 137, in measure_quality
    bblfsh=bblfsh, config_json=config)
  File "/lookout-sdk-ml/lookout/core/helpers/analyzer_context_manager.py", line 87, in review
    log_level=log_level, config_json=config_json)
  File "/lookout-sdk-ml/lookout/core/helpers/server.py", line 101, in review
    return self._run("review", fr, to, port, git_dir, bblfsh, log_level, config_json)
  File "/lookout-sdk-ml/lookout/core/helpers/server.py", line 131, in _run
    return subprocess.run(command, stdout=subprocess.PIPE, stderr=subprocess.PIPE, check=True)
  File "/usr/lib/python3.6/subprocess.py", line 418, in run
    output=stdout, stderr=stderr)
subprocess.CalledProcessError: Command '['/tmp/lookout-sdk-ml/lookout-sdk-v0.7.0', 'review', 'ipv4://localhost:8951', '--from', 'ffd8c1fe19a90bb424faddda1d91b5489b48119e', '--to', '600230efd1b0eeed50b8c386d6cb6e2fbdd9f5f8', '--git-dir', '/tmp/top-repos-quality-repos-ji6vju5k/v1wasm.git', '--log-format', 'json', '--log-level', 'warning', '--config-json', '{"style.format.analyzer.FormatAnalyzer": {"aggregate": true}}']' returned non-zero exit status 1.
--------------------
Failed to process https://github.com/giubatt/project_euler.git repo
Traceback (most recent call last):
  File "/style-analyzer/lookout/style/format/benchmarks/quality_report.py", line 312, in generate_quality_report
    vnodes_expected_number=vnodes_expected_number)
  File "/style-analyzer/lookout/style/format/benchmarks/quality_report.py", line 137, in measure_quality
    bblfsh=bblfsh, config_json=config)
  File "/lookout-sdk-ml/lookout/core/helpers/analyzer_context_manager.py", line 87, in review
    log_level=log_level, config_json=config_json)
  File "/lookout-sdk-ml/lookout/core/helpers/server.py", line 101, in review
    return self._run("review", fr, to, port, git_dir, bblfsh, log_level, config_json)
  File "/lookout-sdk-ml/lookout/core/helpers/server.py", line 131, in _run
    return subprocess.run(command, stdout=subprocess.PIPE, stderr=subprocess.PIPE, check=True)
  File "/usr/lib/python3.6/subprocess.py", line 418, in run
    output=stdout, stderr=stderr)
subprocess.CalledProcessError: Command '['/tmp/lookout-sdk-ml/lookout-sdk-v0.7.0', 'review', 'ipv4://localhost:8951', '--from', '396f4d7a9555ff192459f2f85868e3f948156f69', '--to', '396f4d7a9555ff192459f2f85868e3f948156f69', '--git-dir', '/tmp/top-repos-quality-repos-slta5r6i/project_euler.git', '--log-format', 'json', '--log-level', 'warning', '--config-json', '{"style.format.analyzer.FormatAnalyzer": {"aggregate": true}}']' returned non-zero exit status 1.
--------------------
Failed to process https://github.com/asthzh/configs.git repo
Traceback (most recent call last):
  File "/style-analyzer/lookout/style/format/benchmarks/quality_report.py", line 312, in generate_quality_report
    vnodes_expected_number=vnodes_expected_number)
  File "/style-analyzer/lookout/style/format/benchmarks/quality_report.py", line 135, in measure_quality
    (restarts, repository))
RuntimeError: Run out of 3 attempts. Failed to train proper model for https://github.com/asthzh/configs.git.
--------------------
Failed to process https://github.com/pattamite/swe-kindlekuniya.git repo
Traceback (most recent call last):
  File "/style-analyzer/lookout/style/format/benchmarks/quality_report.py", line 312, in generate_quality_report
    vnodes_expected_number=vnodes_expected_number)
  File "/style-analyzer/lookout/style/format/benchmarks/quality_report.py", line 123, in measure_quality
    git_dir = ensure_repo(repository, tmpdirname)
  File "/style-analyzer/lookout/style/format/benchmarks/quality_report.py", line 54, in ensure_repo
    porcelain.clone(repository, git_dir)
  File "/usr/local/lib/python3.6/dist-packages/dulwich/porcelain.py", line 353, in clone
    depth=depth, **kwargs)
  File "/usr/local/lib/python3.6/dist-packages/dulwich/porcelain.py", line 1121, in fetch
    depth=depth)
  File "/usr/local/lib/python3.6/dist-packages/dulwich/client.py", line 398, in fetch
    progress=progress, depth=depth)
  File "/usr/local/lib/python3.6/dist-packages/dulwich/client.py", line 1644, in fetch_pack
    b"git-upload-pack", url)
  File "/usr/local/lib/python3.6/dist-packages/dulwich/client.py", line 1532, in _discover_references
    resp, read = self._http_request(url, headers, allow_compression=True)
  File "/usr/local/lib/python3.6/dist-packages/dulwich/client.py", line 1510, in _http_request
    (resp.status, url))
dulwich.errors.GitProtocolError: unexpected http resp 401 for https://github.com/pattamite/swe-kindlekuniya.git/info/refs?service=git-upload-pack
--------------------
Failed to process https://github.com/googleworkspace/drive-utils.git repo
Traceback (most recent call last):
  File "/style-analyzer/lookout/style/format/benchmarks/quality_report.py", line 312, in generate_quality_report
    vnodes_expected_number=vnodes_expected_number)
  File "/style-analyzer/lookout/style/format/benchmarks/quality_report.py", line 137, in measure_quality
    bblfsh=bblfsh, config_json=config)
  File "/lookout-sdk-ml/lookout/core/helpers/analyzer_context_manager.py", line 87, in review
    log_level=log_level, config_json=config_json)
  File "/lookout-sdk-ml/lookout/core/helpers/server.py", line 101, in review
    return self._run("review", fr, to, port, git_dir, bblfsh, log_level, config_json)
  File "/lookout-sdk-ml/lookout/core/helpers/server.py", line 131, in _run
    return subprocess.run(command, stdout=subprocess.PIPE, stderr=subprocess.PIPE, check=True)
  File "/usr/lib/python3.6/subprocess.py", line 418, in run
    output=stdout, stderr=stderr)
subprocess.CalledProcessError: Command '['/tmp/lookout-sdk-ml/lookout-sdk-v0.7.0', 'review', 'ipv4://localhost:8951', '--from', '2762e40b6283bf2d6c3486cc3a4aa75d30f9454c', '--to', '2762e40b6283bf2d6c3486cc3a4aa75d30f9454c', '--git-dir', '/tmp/top-repos-quality-repos-9lc_3pmt/drive-utils.git', '--log-format', 'json', '--log-level', 'warning', '--config-json', '{"style.format.analyzer.FormatAnalyzer": {"aggregate": true}}']' returned non-zero exit status 1.
--------------------
Failed to process https://github.com/kaipietila/gloomhaven-partytracker.git repo
Traceback (most recent call last):
  File "/style-analyzer/lookout/style/format/benchmarks/quality_report.py", line 312, in generate_quality_report
    vnodes_expected_number=vnodes_expected_number)
  File "/style-analyzer/lookout/style/format/benchmarks/quality_report.py", line 123, in measure_quality
    git_dir = ensure_repo(repository, tmpdirname)
  File "/style-analyzer/lookout/style/format/benchmarks/quality_report.py", line 54, in ensure_repo
    porcelain.clone(repository, git_dir)
  File "/usr/local/lib/python3.6/dist-packages/dulwich/porcelain.py", line 353, in clone
    depth=depth, **kwargs)
  File "/usr/local/lib/python3.6/dist-packages/dulwich/porcelain.py", line 1121, in fetch
    depth=depth)
  File "/usr/local/lib/python3.6/dist-packages/dulwich/client.py", line 398, in fetch
    progress=progress, depth=depth)
  File "/usr/local/lib/python3.6/dist-packages/dulwich/client.py", line 1644, in fetch_pack
    b"git-upload-pack", url)
  File "/usr/local/lib/python3.6/dist-packages/dulwich/client.py", line 1532, in _discover_references
    resp, read = self._http_request(url, headers, allow_compression=True)
  File "/usr/local/lib/python3.6/dist-packages/dulwich/client.py", line 1510, in _http_request
    (resp.status, url))
dulwich.errors.GitProtocolError: unexpected http resp 401 for https://github.com/kaipietila/gloomhaven-partytracker.git/info/refs?service=git-upload-pack
--------------------
Failed to process https://github.com/ikvt-71/web_dev_project.git repo
Traceback (most recent call last):
  File "/style-analyzer/lookout/style/format/benchmarks/quality_report.py", line 312, in generate_quality_report
    vnodes_expected_number=vnodes_expected_number)
  File "/style-analyzer/lookout/style/format/benchmarks/quality_report.py", line 137, in measure_quality
    bblfsh=bblfsh, config_json=config)
  File "/lookout-sdk-ml/lookout/core/helpers/analyzer_context_manager.py", line 87, in review
    log_level=log_level, config_json=config_json)
  File "/lookout-sdk-ml/lookout/core/helpers/server.py", line 101, in review
    return self._run("review", fr, to, port, git_dir, bblfsh, log_level, config_json)
  File "/lookout-sdk-ml/lookout/core/helpers/server.py", line 131, in _run
    return subprocess.run(command, stdout=subprocess.PIPE, stderr=subprocess.PIPE, check=True)
  File "/usr/lib/python3.6/subprocess.py", line 418, in run
    output=stdout, stderr=stderr)
subprocess.CalledProcessError: Command '['/tmp/lookout-sdk-ml/lookout-sdk-v0.7.0', 'review', 'ipv4://localhost:8951', '--from', '12667ef64e512fb008e6c43e9f6eef2ce8b6832d', '--to', 'c6f1a4fe0c3e98f9112418721def56e4476079a3', '--git-dir', '/tmp/top-repos-quality-repos-6micao8a/web_dev_project.git', '--log-format', 'json', '--log-level', 'warning', '--config-json', '{"style.format.analyzer.FormatAnalyzer": {"aggregate": true}}']' returned non-zero exit status 1.
--------------------
Failed to process https://github.com/gustavofonseca/inbox.git repo
Traceback (most recent call last):
  File "/style-analyzer/lookout/style/format/benchmarks/quality_report.py", line 312, in generate_quality_report
    vnodes_expected_number=vnodes_expected_number)
  File "/style-analyzer/lookout/style/format/benchmarks/quality_report.py", line 135, in measure_quality
    (restarts, repository))
RuntimeError: Run out of 3 attempts. Failed to train proper model for https://github.com/gustavofonseca/inbox.git.
